Workbook

Sheet Worksheet
E1: =IF(OR(AND(H3=1,'OC4000 Values'!M1-60<NOW()),AND(H3=2,'OC3000 Values'!M1-60<NOW())),"WARNING:STANDARD IS DUE","") | I1: =IF(OR(AND(H3=1,'OC4000 Values'!M1<NOW()),AND(H3=2,'OC3000 Values'!M1<NOW())),"STANDARD OVERDUE","") | R1: OC4000
G2: Save As Before Closing!!!! | R2: OC3000
C3: LINEAR AXES TESTING | H3: 2
D4: X Axis | J4: Y Axis
D5: Repeatability: | F5: Reticle Scale | G5: X | J5: Repeatability: | L5: Reticle Scale | M5: Y
C7: Start Pt. | E7: Linear Displacement: | I7: Start Pt. | K7: Linear Displacement:
C8: On Std. | D8: Results | E8: ACTUAL | F8: Inc. Dev. | G8: Abs. Dev. | I8: On Std. | J8: Results | K8: ACTUAL | L8: Inc. Dev. | M8: Abs. Dev.
B9: 1 | C9: 1 | E9: =IFERROR(D9-VLOOKUP(I9,INDIRECT( IF($G$5="X",$P$9,$Q$9) ),4,FALSE),"") -> -5.4e-05 | G9: =IF(D9="","",E9-B9) | H9: =D9-(VLOOKUP(C9,'OC1000 Values'!$C$6:$F$30,4,FALSE)) -> 0 | I9: 1 | K9: =IFERROR(J9-VLOOKUP(I9,INDIRECT( IF($M$5="X",$P$9,$Q$9) ),4,FALSE),"") -> -2.7e-05 | M9: =IF(J9="","",K9-B9) | P9: {=INDEX(Table2[X], $H$3)} -> 'OC3000 Values'!$C$6:$F$30 | Q9: {=INDEX(Table2[Y], $H$3)} -> 'OC3000 Values'!$H$6:$K$18
B10: 2 | C10: 2 | E10: =IFERROR(D10-VLOOKUP(I10,INDIRECT( IF($G$5="X",$P$9,$Q$9) ),4,FALSE),"") -> -7.2e-05 | F10: =IF(D10="","",E10-E9-1) | G10: =IF(D10="","",E10-B10) | I10: =I9+1 -> 2 | K10: =IFERROR(J10-VLOOKUP(I10,INDIRECT( IF($M$5="X",$P$9,$Q$9) ),4,FALSE),"") -> -4.2e-05 | L10: =IF(J10="","",K10-K9-1) | M10: =IF(J10="","",K10-B10) | N10: Index (H3) | O10: Values | P10: X | Q10: Y
B11: 3 | C11: 3 | E11: =IFERROR(D11-VLOOKUP(I11,INDIRECT( IF($G$5="X",$P$9,$Q$9) ),4,FALSE),"") -> -0.000158 | F11: =IF(D11="","",E11-E10-1) | G11: =IF(D11="","",E11-B11) | I11: =I10+1 -> 3 | K11: =IFERROR(J11-VLOOKUP(I11,INDIRECT( IF($M$5="X",$P$9,$Q$9) ),4,FALSE),"") -> -6.4e-05 | L11: =IF(J11="","",K11-K10-1) | M11: =IF(J11="","",K11-B11) | N11: 1 | O11: OC4000 | P11: 'OC4000 Values'!$C$6:$F$30 | Q11: 'OC4000 Values'!$H$6:$K$18
B12: 4 | C12: 4 | E12: =IFERROR(D12-VLOOKUP(I12,INDIRECT( IF($G$5="X",$P$9,$Q$9) ),4,FALSE),"") -> -0.000191 | F12: =IF(D12="","",E12-E11-1) | G12: =IF(D12="","",E12-B12) | I12: =I11+1 -> 4 | K12: =IFERROR(J12-VLOOKUP(I12,INDIRECT( IF($M$5="X",$P$9,$Q$9) ),4,FALSE),"") -> -5.2e-05 | L12: =IF(J12="","",K12-K11-1) | M12: =IF(J12="","",K12-B12) | N12: 2 | O12: OC3000 | P12: 'OC3000 Values'!$C$6:$F$30 | Q12: 'OC3000 Values'!$H$6:$K$18
B13: 5 | C13: 5 | E13: =IFERROR(D13-VLOOKUP(I13,INDIRECT( IF($G$5="X",$P$9,$Q$9) ),4,FALSE),"") -> -0.000194 | F13: =IF(D13="","",E13-E12-1) | G13: =IF(D13="","",E13-B13) | I13: =I12+1 -> 5 | K13: =IFERROR(J13-VLOOKUP(I13,INDIRECT( IF($M$5="X",$P$9,$Q$9) ),4,FALSE),"") -> -6.4e-05 | L13: =IF(J13="","",K13-K12-1) | M13: =IF(J13="","",K13-B13) | N13: 3 | O13: OC1000 | P13: 'OC4000 Values'!$C$6:$F$30
B14: 6 | C14: =C13+1 -> 6 | E14: =IFERROR(D14-VLOOKUP(I14,INDIRECT( IF($G$5="X",$P$9,$Q$9) ),4,FALSE),"") -> -0.000231 | F14: =IF(D14="","",E14-E13-1) | G14: =IF(D14="","",E14-B14) | I14: =I13+1 -> 6 | K14: =IFERROR(J14-VLOOKUP(I14,INDIRECT( IF($M$5="X",$P$9,$Q$9) ),4,FALSE),"") -> -2.7e-05 | L14: =IF(J14="","",K14-K13-1) | M14: =IF(J14="","",K14-B14)
B15: 7 | C15: =C14+1 -> 7 | E15: =IFERROR(D15-VLOOKUP(I15,INDIRECT( IF($G$5="X",$P$9,$Q$9) ),4,FALSE),"") -> -0.000196 | F15: =IF(D15="","",E15-E14-1) | G15: =IF(D15="","",E15-B15) | I15: =I14+1 -> 7 | K15: =IFERROR(J15-VLOOKUP(I15,INDIRECT( IF($M$5="X",$P$9,$Q$9) ),4,FALSE),"") | L15: =IF(J15="","",K15-K14-1) | M15: =IF(J15="","",K15-B15)
B16: 8 | C16: =C15+1 -> 8 | E16: =IFERROR(D16-VLOOKUP(I16,INDIRECT( IF($G$5="X",$P$9,$Q$9) ),4,FALSE),"") -> -0.000247 | F16: =IF(D16="","",E16-E15-1) | G16: =IF(D16="","",E16-B16) | I16: =I15+1 -> 8 | K16: =IFERROR(J16-VLOOKUP(I16,INDIRECT( IF($M$5="X",$P$9,$Q$9) ),4,FALSE),"") | L16: =IF(J16="","",K16-K15-1) | M16: =IF(J16="","",K16-B16)
B17: 9 | C17: =C16+1 -> 9 | E17: =IFERROR(D17-VLOOKUP(I17,INDIRECT( IF($G$5="X",$P$9,$Q$9) ),4,FALSE),"") -> -0.000251 | F17: =IF(D17="","",E17-E16-1) | G17: =IF(D17="","",E17-B17) | I17: =I16+1 -> 9 | K17: =IFERROR(J17-VLOOKUP(I17,INDIRECT( IF($M$5="X",$P$9,$Q$9) ),4,FALSE),"") | L17: =IF(J17="","",K17-K16-1) | M17: =IF(J17="","",K17-B17)
B18: 10 | C18: =C17+1 -> 10 | E18: =IFERROR(D18-VLOOKUP(I18,INDIRECT( IF($G$5="X",$P$9,$Q$9) ),4,FALSE),"") -> -0.000327 | F18: =IF(D18="","",E18-E17-1) | G18: =IF(D18="","",E18-B18) | I18: =I17+1 -> 10 | K18: =IFERROR(J18-VLOOKUP(I18,INDIRECT( IF($M$5="X",$P$9,$Q$9) ),4,FALSE),"") | L18: =IF(J18="","",K18-K17-1) | M18: =IF(J18="","",K18-B18)
B19: 11 | C19: =C18+1 -> 11 | E19: =IFERROR(D19-VLOOKUP(I19,INDIRECT( IF($G$5="X",$P$9,$Q$9) ),4,FALSE),"") -> -0.000338 | F19: =IF(D19="","",E19-E18-1) | G19: =IF(D19="","",E19-B19) | I19: =I18+1 -> 11 | K19: =IFERROR(J19-VLOOKUP(I19,INDIRECT( IF($M$5="X",$P$9,$Q$9) ),4,FALSE),"") | L19: =IF(J19="","",K19-K18-1) | M19: =IF(J19="","",K19-B19)
B20: 12 | C20: =C19+1 -> 12 | E20: =IFERROR(D20-VLOOKUP(I20,INDIRECT( IF($G$5="X",$P$9,$Q$9) ),4,FALSE),"") -> -0.000372 | F20: =IF(D20="","",E20-E19-1) | G20: =IF(D20="","",E20-B20) | I20: =I19+1 -> 12 | K20: =IFERROR(J20-VLOOKUP(I20,INDIRECT( IF($M$5="X",$P$9,$Q$9) ),4,FALSE),"") | L20: =IF(J20="","",K20-K19-1) | M20: =IF(J20="","",K20-B20)
E22: Max Inc. Dev. | F22: =MAX(E24:E26) -> 0 | K22: Max Inc. Dev. | L22: =MAX(K24:K26) -> 0
E23: Max Abs. Dev. | F23: =MAX(F24:F26) -> 0 | K23: Max Abs. Dev. | L23: =MAX(L24:L26) -> 0
D24: Max | E24: =MAX(F10:F21) -> 0 | F24: =MAX(G9:G21) -> 0 | J24: Max | K24: =MAX(L10:L21) -> 0 | L24: =MAX(M9:M21) -> 0
D25: Min | E25: =MIN(F10:F20) -> 0 | F25: =MIN(G9:G20) -> 0 | J25: Min | K25: =MIN(L10:L20) -> 0 | L25: =MIN(M9:M20) -> 0
D26: Abs Min | E26: =ABS(E25) -> 0 | F26: =ABS(F25) -> 0 | J26: Abs Min | K26: =ABS(K25) -> 0 | L26: =ABS(L25) -> 0
C28: MAGINIFICATION TESTING | J28: Angle Testing
D29: Setting used on Magscale: | E29: 10 | F29: X | K29: Standard Angle Values | M29: Protractor Results: | O29: (Decimal Degrees can be entered in the "DEG" column) | R29: OC1000 | X29: Dev
D30: Comparator Magnification: | E30: 10 | F30: X | J30: Nominal | K30: Actual | L30: =IF($H$3=1,'OC1000 Values'!Q5,'OC3000 Values'!Q5) -> Dev. | M30: Deg | N30: Min | O30: Sec | P30: Deviation (DMS) | Q30: Deviation (decimal round as needed) | T30: Std Cnts | U30: UUT Cnts | V30: Difference | X30: Deg | Y30: Min | Z30: Sec | AB30: dec deg dev
B31: Circle Measured: | D31: Magnified Standard Diameter | F31: Reading: | G31: Deviation | H31: Tolerance | J31: 15 | K31: =IF($H$3=1,'OC4000 Values'!P6,'OC3000 Values'!P6) -> 14.9989 | L31: =IF($H$3=1,'OC4000 Values'!Q6,'OC3000 Values'!Q6) -> -0.0011 | P31: =IF(M31<>"",CONCATENATE(X31,"° ",Y31,"' ",Z31,"'' "),"") | Q31: =X31+AB31+AC31 -> 0 | S31: =ABS(V31) -> 0 | T31: =IF($H$3=1,'OC4000 Values'!V6,'OC3000 Values'!V6) -> 53996.04 | U31: =O31+(N31*60)+(M31*60*60) -> 0 | V31: =IF(U31=0,0,U31-T31) -> 0 | W31: =IF(T31>U31,-1,1) -> -1 | X31: =IF(W31=1,ROUNDDOWN(V31/60/60,0),ROUNDDOWN(V31/60/60,0)) -> 0 | Y31: =IF(W31=1,ROUNDDOWN((V31/60)-(X31*60),0),ROUNDDOWN((V31/60)-(X31*60),0)) -> 0 | Z31: =ROUND(V31-(Y31*60)-(X31*60*60),1) -> 0 | AA31: =P31 | AB31: =Y31/60 -> 0 | AC31: =Z31/60/60 -> 0
B32: B | D32: =IF($H$3=1,$E$30*(VLOOKUP(B32,'OC1000 Values'!$L$5:$M$27,2,FALSE)),$E$30*(VLOOKUP(B32,'OC3000 Values'!$L$5:$M$27,2,FALSE))) -> 2.4989 | G32: =IF(I32<>"",((I32-D32)/D32),"") | H32: =IF(F32<>"",0.5%,"") | I32: =IF(F32<>"",F32*$E$29,"") | J32: 30 | K32: =IF($H$3=1,'OC4000 Values'!P7,'OC3000 Values'!P7) -> 29.9967 | L32: =IF($H$3=1,'OC4000 Values'!Q7,'OC3000 Values'!Q7) -> -0.0033 | P32: =IF(M32<>"",CONCATENATE(X32,"° ",Y32,"' ",Z32,"'' "),"") | Q32: =X32+AB32+AC32 -> 0 | S32: =ABS(V32) -> 0 | T32: =IF($H$3=1,'OC4000 Values'!V7,'OC3000 Values'!V7) -> 107988.12 | U32: =O32+(N32*60)+(M32*60*60) -> 0 | V32: =IF(U32=0,0,U32-T32) -> 0 | W32: =IF(T32>U32,-1,1) -> -1 | X32: =IF(W32=1,ROUNDDOWN(V32/60/60,0),ROUNDDOWN(V32/60/60,0)) -> 0 | Y32: =IF(W32=1,ROUNDDOWN((V32/60)-(X32*60),0),ROUNDDOWN((V32/60)-(X32*60),0)) -> 0 | Z32: =ROUND(V32-(Y32*60)-(X32*60*60),1) -> 0 | AA32: =P32 | AB32: =Y32/60 -> 0 | AC32: =Z32/60/60 -> 0
B33: C | D33: =IF($H$3=1,$E$30*(VLOOKUP(B33,'OC1000 Values'!$L$5:$M$27,2,FALSE)),$E$30*(VLOOKUP(B33,'OC3000 Values'!$L$5:$M$27,2,FALSE))) -> 6.2488 | G33: =IF(I33<>"",((I33-D33)/D33),"") | H33: =IF(F33<>"",0.5%,"") | I33: =IF(F33<>"",F33*$E$29,"") | J33: 45 | K33: =IF($H$3=1,'OC4000 Values'!P8,'OC3000 Values'!P8) -> 44.9963 | L33: =IF($H$3=1,'OC4000 Values'!Q8,'OC3000 Values'!Q8) -> -0.0037 | P33: =IF(M33<>"",CONCATENATE(X33,"° ",Y33,"' ",Z33,"'' "),"") | Q33: =X33+AB33+AC33 -> 0 | S33: =ABS(V33) -> 0 | T33: =IF($H$3=1,'OC4000 Values'!V8,'OC3000 Values'!V8) -> 161986.68 | U33: =O33+(N33*60)+(M33*60*60) -> 0 | V33: =IF(U33=0,0,U33-T33) -> 0 | W33: =IF(T33>U33,-1,1) -> -1 | X33: =IF(W33=1,ROUNDDOWN(V33/60/60,0),ROUNDDOWN(V33/60/60,0)) -> 0 | Y33: =IF(W33=1,ROUNDDOWN((V33/60)-(X33*60),0),ROUNDDOWN((V33/60)-(X33*60),0)) -> 0 | Z33: =ROUND(V33-(Y33*60)-(X33*60*60),1) -> 0 | AA33: =P33 | AB33: =Y33/60 -> 0 | AC33: =Z33/60/60 -> 0
B34: F | D34: =IF($H$3=1,$E$30*(VLOOKUP(B34,'OC1000 Values'!$L$5:$M$27,2,FALSE)),$E$30*(VLOOKUP(B34,'OC3000 Values'!$L$5:$M$27,2,FALSE))) -> 0.6239 | G34: =IF(I34<>"",((I34-D34)/D34),"") | H34: =IF(F34<>"",0.5%,"") | I34: =IF(F34<>"",F34*$E$29,"") | J34: 60 | K34: =IF($H$3=1,'OC4000 Values'!P9,'OC3000 Values'!P9) -> 59.9962 | L34: =IF($H$3=1,'OC4000 Values'!Q9,'OC3000 Values'!Q9) -> -0.0038 | P34: =IF(M34<>"",CONCATENATE(X34,"° ",Y34,"' ",Z34,"'' "),"") | Q34: =X34+AB34+AC34 -> 0 | S34: =ABS(V34) -> 0 | T34: =IF($H$3=1,'OC4000 Values'!V9,'OC3000 Values'!V9) -> 215986.32 | U34: =O34+(N34*60)+(M34*60*60) -> 0 | V34: =IF(U34=0,0,U34-T34) -> 0 | W34: =IF(T34>U34,-1,1) -> -1 | X34: =IF(W34=1,ROUNDDOWN(V34/60/60,0),ROUNDDOWN(V34/60/60,0)) -> 0 | Y34: =IF(W34=1,ROUNDDOWN((V34/60)-(X34*60),0),ROUNDDOWN((V34/60)-(X34*60),0)) -> 0 | Z34: =ROUND(V34-(Y34*60)-(X34*60*60),1) -> 0 | AA34: =P34 | AB34: =Y34/60 -> 0 | AC34: =Z34/60/60 -> 0
B35: H | D35: =IF($H$3=1,$E$30*(VLOOKUP(B35,'OC1000 Values'!$L$5:$M$27,2,FALSE)),$E$30*(VLOOKUP(B35,'OC3000 Values'!$L$5:$M$27,2,FALSE))) -> 2.4991 | G35: =IF(I35<>"",((I35-D35)/D35),"") | H35: =IF(F35<>"",0.5%,"") | I35: =IF(F35<>"",F35*$E$29,"") | J35: 75 | K35: =IF($H$3=1,'OC4000 Values'!P10,'OC3000 Values'!P10) -> 74.9969 | L35: =IF($H$3=1,'OC4000 Values'!Q10,'OC3000 Values'!Q10) -> -0.0031 | P35: =IF(M35<>"",CONCATENATE(X35,"° ",Y35,"' ",Z35,"'' "),"") | Q35: =X35+AB35+AC35 -> 0 | S35: =ABS(V35) -> 0 | T35: =IF($H$3=1,'OC4000 Values'!V10,'OC3000 Values'!V10) -> 269988.84 | U35: =O35+(N35*60)+(M35*60*60) -> 0 | V35: =IF(U35=0,0,U35-T35) -> 0 | W35: =IF(T35>U35,-1,1) -> -1 | X35: =IF(W35=1,ROUNDDOWN(V35/60/60,0),ROUNDDOWN(V35/60/60,0)) -> 0 | Y35: =IF(W35=1,ROUNDDOWN((V35/60)-(X35*60),0),ROUNDDOWN((V35/60)-(X35*60),0)) -> 0 | Z35: =ROUND(V35-(Y35*60)-(X35*60*60),1) -> 0 | AA35: =P35 | AB35: =Y35/60 -> 0 | AC35: =Z35/60/60 -> 0
D36: =IF($H$3=1,$E$30*(VLOOKUP(B36,'OC1000 Values'!$L$5:$M$27,2,FALSE)),$E$30*(VLOOKUP(B36,'OC3000 Values'!$L$5:$M$27,2,FALSE))) -> #N/A | G36: =IF(I36<>"",((I36-D36)/D36),"") | H36: =IF(F36<>"",0.5%,"") | I36: =IF(F36<>"",F36*$E$29,"") | J36: 90 | K36: =IF($H$3=1,'OC4000 Values'!P11,'OC3000 Values'!P11) -> 89.9996 | L36: =IF($H$3=1,'OC4000 Values'!Q11,'OC3000 Values'!Q11) -> -0.0004 | P36: =IF(M36<>"",CONCATENATE(X36,"° ",Y36,"' ",Z36,"'' "),"") | Q36: =X36+AB36+AC36 -> 0 | S36: =ABS(V36) -> 0 | T36: =IF($H$3=1,'OC4000 Values'!V11,'OC3000 Values'!V11) -> 323998.56 | U36: =O36+(N36*60)+(M36*60*60) -> 0 | V36: =IF(U36=0,0,U36-T36) -> 0 | W36: =IF(T36>U36,-1,1) -> -1 | X36: =IF(W36=1,ROUNDDOWN(V36/60/60,0),ROUNDDOWN(V36/60/60,0)) -> 0 | Y36: =IF(W36=1,ROUNDDOWN((V36/60)-(X36*60),0),ROUNDDOWN((V36/60)-(X36*60),0)) -> 0 | Z36: =ROUND(V36-(Y36*60)-(X36*60*60),1) -> 0 | AA36: =P36 | AB36: =Y36/60 -> 0 | AC36: =Z36/60/60 -> 0
D37: =IF($H$3=1,$E$30*(VLOOKUP(B37,'OC1000 Values'!$L$5:$M$27,2,FALSE)),$E$30*(VLOOKUP(B37,'OC3000 Values'!$L$5:$M$27,2,FALSE))) -> #N/A | G37: =IF(I37<>"",((I37-D37)/D37),"") | H37: =IF(F37<>"",0.5%,"") | I37: =IF(F37<>"",F37*$E$29,"") | J37: 105 | K37: =IF($H$3=1,'OC4000 Values'!P12,'OC3000 Values'!P12) -> 104.997 | L37: =IF($H$3=1,'OC4000 Values'!Q12,'OC3000 Values'!Q12) -> -0.003 | P37: =IF(M37<>"",CONCATENATE(X37,"° ",Y37,"' ",Z37,"'' "),"") | Q37: =X37+AB37+AC37 -> 0 | S37: =ABS(V37) -> 0 | T37: =IF($H$3=1,'OC4000 Values'!V12,'OC3000 Values'!V12) -> 377989.2 | U37: =O37+(N37*60)+(M37*60*60) -> 0 | V37: =IF(U37=0,0,U37-T37) -> 0 | W37: =IF(T37>U37,-1,1) -> -1 | X37: =IF(W37=1,ROUNDDOWN(V37/60/60,0),ROUNDDOWN(V37/60/60,0)) -> 0 | Y37: =IF(W37=1,ROUNDDOWN((V37/60)-(X37*60),0),ROUNDDOWN((V37/60)-(X37*60),0)) -> 0 | Z37: =ROUND(V37-(Y37*60)-(X37*60*60),1) -> 0 | AA37: =P37 | AB37: =Y37/60 -> 0 | AC37: =Z37/60/60 -> 0
D38: =IF($H$3=1,$E$30*(VLOOKUP(B38,'OC1000 Values'!$L$5:$M$27,2,FALSE)),$E$30*(VLOOKUP(B38,'OC3000 Values'!$L$5:$M$27,2,FALSE))) -> #N/A | G38: =IF(I38<>"",((I38-D38)/D38),"") | H38: =IF(F38<>"",0.5%,"") | I38: =IF(F38<>"",F38*$E$29,"") | J38: 120 | K38: =IF($H$3=1,'OC4000 Values'!P13,'OC3000 Values'!P13) -> 119.9963 | L38: =IF($H$3=1,'OC4000 Values'!Q13,'OC3000 Values'!Q13) -> -0.0037 | P38: =IF(M38<>"",CONCATENATE(X38,"° ",Y38,"' ",Z38,"'' "),"") | Q38: =X38+AB38+AC38 -> 0 | S38: =ABS(V38) -> 0 | T38: =IF($H$3=1,'OC4000 Values'!V13,'OC3000 Values'!V13) -> 431986.68 | U38: =O38+(N38*60)+(M38*60*60) -> 0 | V38: =IF(U38=0,0,U38-T38) -> 0 | W38: =IF(T38>U38,-1,1) -> -1 | X38: =IF(W38=1,ROUNDDOWN(V38/60/60,0),ROUNDDOWN(V38/60/60,0)) -> 0 | Y38: =IF(W38=1,ROUNDDOWN((V38/60)-(X38*60),0),ROUNDDOWN((V38/60)-(X38*60),0)) -> 0 | Z38: =ROUND(V38-(Y38*60)-(X38*60*60),1) -> 0 | AA38: =P38 | AB38: =Y38/60 -> 0 | AC38: =Z38/60/60 -> 0
D39: =IF($H$3=1,$E$30*(VLOOKUP(B39,'OC1000 Values'!$L$5:$M$27,2,FALSE)),$E$30*(VLOOKUP(B39,'OC3000 Values'!$L$5:$M$27,2,FALSE))) -> #N/A | G39: =IF(I39<>"",((I39-D39)/D39),"") | H39: =IF(F39<>"",0.5%,"") | I39: =IF(F39<>"",F39*$E$29,"") | J39: 135 | K39: =IF($H$3=1,'OC4000 Values'!P14,'OC3000 Values'!P14) -> 134.9975 | L39: =IF($H$3=1,'OC4000 Values'!Q14,'OC3000 Values'!Q14) -> -0.0025 | P39: =IF(M39<>"",CONCATENATE(X39,"° ",Y39,"' ",Z39,"'' "),"") | Q39: =X39+AB39+AC39 -> 0 | S39: =ABS(V39) -> 0 | T39: =IF($H$3=1,'OC4000 Values'!V14,'OC3000 Values'!V14) -> 485991 | U39: =O39+(N39*60)+(M39*60*60) -> 0 | V39: =IF(U39=0,0,U39-T39) -> 0 | W39: =IF(T39>U39,-1,1) -> -1 | X39: =IF(W39=1,ROUNDDOWN(V39/60/60,0),ROUNDDOWN(V39/60/60,0)) -> 0 | Y39: =IF(W39=1,ROUNDDOWN((V39/60)-(X39*60),0),ROUNDDOWN((V39/60)-(X39*60),0)) -> 0 | Z39: =ROUND(V39-(Y39*60)-(X39*60*60),1) -> 0 | AA39: =P39 | AB39: =Y39/60 -> 0 | AC39: =Z39/60/60 -> 0
D40: =IF($H$3=1,$E$30*(VLOOKUP(B40,'OC1000 Values'!$L$5:$M$27,2,FALSE)),$E$30*(VLOOKUP(B40,'OC3000 Values'!$L$5:$M$27,2,FALSE))) -> #N/A | G40: =IF(I40<>"",((I40-D40)/D40),"") | H40: =IF(F40<>"",0.5%,"") | I40: =IF(F40<>"",F40*$E$29,"") | J40: 150 | K40: =IF($H$3=1,'OC4000 Values'!P15,'OC3000 Values'!P15) -> 149.9988 | L40: =IF($H$3=1,'OC4000 Values'!Q15,'OC3000 Values'!Q15) -> -0.0012 | P40: =IF(M40<>"",CONCATENATE(X40,"° ",Y40,"' ",Z40,"'' "),"") | Q40: =X40+AB40+AC40 -> 0 | S40: =ABS(V40) -> 0 | T40: =IF($H$3=1,'OC4000 Values'!V15,'OC3000 Values'!V15) -> 539995.68 | U40: =O40+(N40*60)+(M40*60*60) -> 0 | V40: =IF(U40=0,0,U40-T40) -> 0 | W40: =IF(T40>U40,-1,1) -> -1 | X40: =IF(W40=1,ROUNDDOWN(V40/60/60,0),ROUNDDOWN(V40/60/60,0)) -> 0 | Y40: =IF(W40=1,ROUNDDOWN((V40/60)-(X40*60),0),ROUNDDOWN((V40/60)-(X40*60),0)) -> 0 | Z40: =ROUND(V40-(Y40*60)-(X40*60*60),1) -> 0 | AA40: =P40 | AB40: =Y40/60 -> 0 | AC40: =Z40/60/60 -> 0
D41: =IF($H$3=1,$E$30*(VLOOKUP(B41,'OC1000 Values'!$L$5:$M$27,2,FALSE)),$E$30*(VLOOKUP(B41,'OC3000 Values'!$L$5:$M$27,2,FALSE))) -> #N/A | G41: =IF(I41<>"",((I41-D41)/D41),"") | H41: =IF(F41<>"",0.5%,"") | I41: =IF(F41<>"",F41*$E$29,"") | J41: 165 | K41: =IF($H$3=1,'OC4000 Values'!P16,'OC3000 Values'!P16) -> 164.9941 | L41: =IF($H$3=1,'OC4000 Values'!Q16,'OC3000 Values'!Q16) -> -0.0059 | P41: =IF(M41<>"",CONCATENATE(X41,"° ",Y41,"' ",Z41,"'' "),"") | Q41: =X41+AB41+AC41 -> 0 | S41: =ABS(V41) -> 0 | T41: =IF($H$3=1,'OC4000 Values'!V16,'OC3000 Values'!V16) -> 593978.76 | U41: =O41+(N41*60)+(M41*60*60) -> 0 | V41: =IF(U41=0,0,U41-T41) -> 0 | W41: =IF(T41>U41,-1,1) -> -1 | X41: =IF(W41=1,ROUNDDOWN(V41/60/60,0),ROUNDDOWN(V41/60/60,0)) -> 0 | Y41: =IF(W41=1,ROUNDDOWN((V41/60)-(X41*60),0),ROUNDDOWN((V41/60)-(X41*60),0)) -> 0 | Z41: =ROUND(V41-(Y41*60)-(X41*60*60),1) -> 0 | AA41: =P41 | AB41: =Y41/60 -> 0 | AC41: =Z41/60/60 -> 0
D42: =IF($H$3=1,$E$30*(VLOOKUP(B42,'OC1000 Values'!$L$5:$M$27,2,FALSE)),$E$30*(VLOOKUP(B42,'OC3000 Values'!$L$5:$M$27,2,FALSE))) -> #N/A | G42: =IF(I42<>"",((I42-D42)/D42),"") | H42: =IF(F42<>"",0.5%,"") | I42: =IF(F42<>"",F42*$E$29,"") | J42: 180 | K42: =IF($H$3=1,'OC4000 Values'!P17,'OC3000 Values'!P17) -> 179.9966 | L42: =IF($H$3=1,'OC4000 Values'!Q17,'OC3000 Values'!Q17) -> -0.0034 | P42: =IF(M42<>"",CONCATENATE(X42,"° ",Y42,"' ",Z42,"'' "),"") | Q42: =X42+AB42+AC42 -> 0 | S42: =ABS(V42) -> 0 | T42: =IF($H$3=1,'OC4000 Values'!V17,'OC3000 Values'!V17) -> 647987.76 | U42: =O42+(N42*60)+(M42*60*60) -> 0 | V42: =IF(U42=0,0,U42-T42) -> 0 | W42: =IF(T42>U42,-1,1) -> -1 | X42: =IF(W42=1,ROUNDDOWN(V42/60/60,0),ROUNDDOWN(V42/60/60,0)) -> 0 | Y42: =IF(W42=1,ROUNDDOWN((V42/60)-(X42*60),0),ROUNDDOWN((V42/60)-(X42*60),0)) -> 0 | Z42: =ROUND(V42-(Y42*60)-(X42*60*60),1) -> 0 | AA42: =P42 | AB42: =Y42/60 -> 0 | AC42: =Z42/60/60 -> 0
D43: =IF($H$3=1,$E$30*(VLOOKUP(B43,'OC1000 Values'!$L$5:$M$27,2,FALSE)),$E$30*(VLOOKUP(B43,'OC3000 Values'!$L$5:$M$27,2,FALSE))) -> #N/A | G43: =IF(I43<>"",((I43-D43)/D43),"") | H43: =IF(F43<>"",0.5%,"") | I43: =IF(F43<>"",F43*$E$29,"") | S43: =MAX(S31:S42) -> 0 | T43: =VLOOKUP(S43,S31:AA42,9,FALSE)

Sheet Machine info
A1: Report No. | D1: RESULTS
A2: Customer | E2: X AXIS
A3: Item | E3: L.D.A Incremental | F3: =IF(Worksheet!D9<>"",Worksheet!F22,"")
A4: Model No. | E4: L.D.A Maximum | F4: =IF(Worksheet!D9<>"",Worksheet!F23,"")
A5: Unit No. | E5: Repeatability | F5: =IF(Worksheet!E5="","",Worksheet!E5)
A6: Serial No.
A7: Location
A8: Inspector | E8: Y AXIS
A9: Date Cal. | E9: L.D.A Incremental | F9: =IF(Worksheet!J9<>"",Worksheet!L22,"")
A10: Date Due | E10: L.D.A Maximum | F10: =IF(Worksheet!J9<>"",Worksheet!L23,"")
A11: Temp. | E11: Repeatability | F11: =IF(Worksheet!K5="","",Worksheet!K5)
A12: Humidity
A13: X Axis Range
A14: Y Axis Range | E14: Magnification Error(Avg) | F14: =IFERROR(AVERAGE(Worksheet!G32:G43),"")
A15: Scale Res. | E15: Protractor Error(Max) | F15: =Worksheet!T43
A16: Protractor Res.
A17: Lens Mag.

Sheet OC3000 Values
K1: Due Date | M1: =DATE(YEAR(M2)+3,MONTH(M2),DAY(M2)) -> 46567
F2: GAGE LINE RETICLE CERTIFICATION VALUES | K2: Calibration Date | M2: 45472
C3: OC3000 VALUES
C4: Top Inch Scale | H4: Vertical Inch Scale | L4: CIRCLES | M4: ACTUAL SIZE | O4: ANGLES | S4: Standard Counts | W4: minutes extracted | X4: Extraction | AC4: seconds extracted
C5: Nominal | D5: error (µ") | E5: Actual | H5: Nominal | I5: error (µ") | J5: Actual | L5: A | M5: 0.06241 | O5: Nominal | P5: ACTUAL VALUES | Q5: Dev. | S5: Deg | T5: Min | U5: Sec | V5: Std Counts | X5: Deg | Y5: Min | Z5: seconds extractor | AD5: Sec
C6: 0 | E6: =(D6*0.000001)+C6 -> 0 | F6: =E6-C6 -> 0 | H6: 0 | J6: =(I6*0.000001)+H6 -> 0 | K6: =J6-H6 -> 0 | L6: B | M6: 0.24989 | O6: 15 | P6: 14.9989 | Q6: =P6-O6 -> -0.0011 | S6: =X6 -> 14 | T6: =Z6 -> 59 | U6: =AD6 -> 56.04 | V6: =U6+(T6*60)+(S6*60*60) -> 53996.04 | W6: =O6-ROUNDDOWN(P6,0)+Q6 -> 0.9989 | X6: =VALUE(LEFT(P6,2)) -> 14 | Y6: =W6*60 -> 59.934 | Z6: =VALUE(LEFT(Y6,2)) -> 59 | AA6: =60-Y6 -> 0.066 | AB6: =60-ROUNDDOWN(Y6,0) -> 1 | AC6: =AB6-AA6 -> 0.934 | AD6: =AC6*60 -> 56.04
C7: 0.5 | E7: 0.500014 | F7: =E7-C7 -> 1.4e-05 | H7: 0.5 | I7: =K7*1000000 -> 17 | J7: 0.500017 | K7: =J7-H7 -> 1.7e-05 | L7: C | M7: 0.62488 | O7: 30 | P7: 29.9967 | Q7: =P7-O7 -> -0.0033 | S7: =X7 -> 29 | T7: =Z7 -> 59 | U7: =AD7 -> 48.12 | V7: =U7+(T7*60)+(S7*60*60) -> 107988.12 | W7: =O7-ROUNDDOWN(P7,0)+Q7 -> 0.9967 | X7: =VALUE(LEFT(P7,2)) -> 29 | Y7: =W7*60 -> 59.802 | Z7: =VALUE(LEFT(Y7,2)) -> 59 | AA7: =60-Y7 -> 0.198 | AB7: =60-ROUNDDOWN(Y7,0) -> 1 | AC7: =AB7-AA7 -> 0.802 | AD7: =AC7*60 -> 48.12
C8: 1 | E8: 1.000054 | F8: =E8-C8 -> 5.4e-05 | H8: 1 | I8: =K8*1000000 -> 27 | J8: 1.000027 | K8: =J8-H8 -> 2.7e-05 | L8: D | M8: 0.99986 | O8: 45 | P8: 44.9963 | Q8: =P8-O8 -> -0.0037 | S8: =X8 -> 44 | T8: =Z8 -> 59 | U8: =AD8 -> 46.68 | V8: =U8+(T8*60)+(S8*60*60) -> 161986.68 | W8: =O8-ROUNDDOWN(P8,0)+Q8 -> 0.9963 | X8: =VALUE(LEFT(P8,2)) -> 44 | Y8: =W8*60 -> 59.778 | Z8: =VALUE(LEFT(Y8,2)) -> 59 | AA8: =60-Y8 -> 0.222 | AB8: =60-ROUNDDOWN(Y8,0) -> 1 | AC8: =AB8-AA8 -> 0.778 | AD8: =AC8*60 -> 46.68
C9: 1.5 | E9: 1.500084 | F9: =E9-C9 -> 8.4e-05 | H9: 1.5 | I9: =K9*1000000 -> 24 | J9: 1.500024 | K9: =J9-H9 -> 2.4e-05 | L9: E | M9: 1.24985 | O9: 60 | P9: 59.9962 | Q9: =P9-O9 -> -0.0038 | S9: =X9 -> 59 | T9: =Z9 -> 59 | U9: =AD9 -> 46.32 | V9: =U9+(T9*60)+(S9*60*60) -> 215986.32 | W9: =O9-ROUNDDOWN(P9,0)+Q9 -> 0.9962 | X9: =VALUE(LEFT(P9,2)) -> 59 | Y9: =W9*60 -> 59.772 | Z9: =VALUE(LEFT(Y9,2)) -> 59 | AA9: =60-Y9 -> 0.228 | AB9: =60-ROUNDDOWN(Y9,0) -> 1 | AC9: =AB9-AA9 -> 0.772 | AD9: =AC9*60 -> 46.32
C10: 2 | E10: 2.000072 | F10: =E10-C10 -> 7.2e-05 | H10: 2 | I10: =K10*1000000 -> 42 | J10: 2.000042 | K10: =J10-H10 -> 4.2e-05 | L10: F | M10: 0.06239 | O10: 75 | P10: 74.9969 | Q10: =P10-O10 -> -0.0031 | S10: =X10 -> 74 | T10: =Z10 -> 59 | U10: =AD10 -> 48.84 | V10: =U10+(T10*60)+(S10*60*60) -> 269988.84 | W10: =O10-ROUNDDOWN(P10,0)+Q10 -> 0.9969 | X10: =VALUE(LEFT(P10,2)) -> 74 | Y10: =W10*60 -> 59.814 | Z10: =VALUE(LEFT(Y10,2)) -> 59 | AA10: =60-Y10 -> 0.186 | AB10: =60-ROUNDDOWN(Y10,0) -> 1 | AC10: =AB10-AA10 -> 0.814 | AD10: =AC10*60 -> 48.84
C11: 2.5 | E11: 2.500116 | F11: =E11-C11 -> 0.000116 | H11: 2.5 | I11: =K11*1000000 -> 67 | J11: 2.500067 | K11: =J11-H11 -> 6.7e-05 | L11: G | M11: 0.18742 | O11: 90 | P11: 89.9996 | Q11: =P11-O11 -> -0.0004 | S11: =X11 -> 89 | T11: =Z11 -> 59 | U11: =AD11 -> 58.56 | V11: =U11+(T11*60)+(S11*60*60) -> 323998.56 | W11: =O11-ROUNDDOWN(P11,0)+Q11 -> 0.9996 | X11: =VALUE(LEFT(P11,2)) -> 89 | Y11: =W11*60 -> 59.976 | Z11: =VALUE(LEFT(Y11,2)) -> 59 | AA11: =60-Y11 -> 0.024 | AB11: =60-ROUNDDOWN(Y11,0) -> 1 | AC11: =AB11-AA11 -> 0.976 | AD11: =AC11*60 -> 58.56
C12: 3 | E12: 3.000158 | F12: =E12-C12 -> 0.000158 | H12: 3 | I12: =K12*1000000 -> 64 | J12: 3.000064 | K12: =J12-H12 -> 6.4e-05 | L12: H | M12: 0.24991 | O12: 105 | P12: 104.997 | Q12: =P12-O12 -> -0.003 | S12: =X12 -> 104 | T12: =Z12 -> 59 | U12: =AD12 -> 49.2 | V12: =U12+(T12*60)+(S12*60*60) -> 377989.2 | W12: =O12-ROUNDDOWN(P12,0)+Q12 -> 0.997 | X12: =VALUE(LEFT(P12,3)) -> 104 | Y12: =W12*60 -> 59.82 | Z12: =VALUE(LEFT(Y12,2)) -> 59 | AA12: =60-Y12 -> 0.18 | AB12: =60-ROUNDDOWN(Y12,0) -> 1 | AC12: =AB12-AA12 -> 0.82 | AD12: =AC12*60 -> 49.2
C13: 3.5 | E13: 3.500156 | F13: =E13-C13 -> 0.000156 | H13: 3.5 | I13: =K13*1000000 -> 53 | J13: 3.500053 | K13: =J13-H13 -> 5.3e-05 | L13: J | M13: 0.43741 | O13: 120 | P13: 119.9963 | Q13: =P13-O13 -> -0.0037 | S13: =X13 -> 119 | T13: =Z13 -> 59 | U13: =AD13 -> 46.68 | V13: =U13+(T13*60)+(S13*60*60) -> 431986.68 | W13: =O13-ROUNDDOWN(P13,0)+Q13 -> 0.9963 | X13: =VALUE(LEFT(P13,3)) -> 119 | Y13: =W13*60 -> 59.778 | Z13: =VALUE(LEFT(Y13,2)) -> 59 | AA13: =60-Y13 -> 0.222 | AB13: =60-ROUNDDOWN(Y13,0) -> 1 | AC13: =AB13-AA13 -> 0.778 | AD13: =AC13*60 -> 46.68
C14: 4 | E14: 4.000191 | F14: =E14-C14 -> 0.000191 | H14: 4 | I14: =K14*1000000 -> 52 | J14: 4.000052 | K14: =J14-H14 -> 5.2e-05 | L14: K | M14: 0.6249 | O14: 135 | P14: 134.9975 | Q14: =P14-O14 -> -0.0025 | S14: =X14 -> 134 | T14: =Z14 -> 59 | U14: =AD14 -> 51 | V14: =U14+(T14*60)+(S14*60*60) -> 485991 | W14: =O14-ROUNDDOWN(P14,0)+Q14 -> 0.9975 | X14: =VALUE(LEFT(P14,3)) -> 134 | Y14: =W14*60 -> 59.85 | Z14: =VALUE(LEFT(Y14,2)) -> 59 | AA14: =60-Y14 -> 0.15 | AB14: =60-ROUNDDOWN(Y14,0) -> 1 | AC14: =AB14-AA14 -> 0.85 | AD14: =AC14*60 -> 51
C15: 4.5 | E15: 4.500215 | F15: =E15-C15 -> 0.000215 | H15: 4.5 | I15: =K15*1000000 -> 42 | J15: 4.500042 | K15: =J15-H15 -> 4.2e-05 | L15: L | M15: 0.06245 | O15: 150 | P15: 149.9988 | Q15: =P15-O15 -> -0.0012 | S15: =X15 -> 149 | T15: =Z15 -> 59 | U15: =AD15 -> 55.68 | V15: =U15+(T15*60)+(S15*60*60) -> 539995.68 | W15: =O15-ROUNDDOWN(P15,0)+Q15 -> 0.9988 | X15: =VALUE(LEFT(P15,3)) -> 149 | Y15: =W15*60 -> 59.928 | Z15: =VALUE(LEFT(Y15,2)) -> 59 | AA15: =60-Y15 -> 0.072 | AB15: =60-ROUNDDOWN(Y15,0) -> 1 | AC15: =AB15-AA15 -> 0.928 | AD15: =AC15*60 -> 55.68
C16: 5 | E16: 5.000194 | F16: =E16-C16 -> 0.000194 | H16: 5 | I16: =K16*1000000 -> 64 | J16: 5.000064 | K16: =J16-H16 -> 6.4e-05 | L16: M | M16: 0.12495 | O16: 165 | P16: 164.9941 | Q16: =P16-O16 -> -0.0059 | S16: =X16 -> 164 | T16: =Z16 -> 59 | U16: =AD16 -> 38.76 | V16: =U16+(T16*60)+(S16*60*60) -> 593978.76 | W16: =O16-ROUNDDOWN(P16,0)+Q16 -> 0.9941 | X16: =VALUE(LEFT(P16,3)) -> 164 | Y16: =W16*60 -> 59.646 | Z16: =VALUE(LEFT(Y16,2)) -> 59 | AA16: =60-Y16 -> 0.354 | AB16: =60-ROUNDDOWN(Y16,0) -> 1 | AC16: =AB16-AA16 -> 0.646 | AD16: =AC16*60 -> 38.76
C17: 5.5 | E17: 5.500213 | F17: =E17-C17 -> 0.000213 | H17: 5.5 | I17: =K17*1000000 -> 18 | J17: 5.500018 | K17: =J17-H17 -> 1.8e-05 | L17: N | M17: 0.18748 | O17: 180 | P17: 179.9966 | Q17: =P17-O17 -> -0.0034 | S17: =X17 -> 179 | T17: =Z17 -> 59 | U17: =AD17 -> 47.76 | V17: =U17+(T17*60)+(S17*60*60) -> 647987.76 | W17: =O17-ROUNDDOWN(P17,0)+Q17 -> 0.9966 | X17: =VALUE(LEFT(P17,3)) -> 179 | Y17: =W17*60 -> 59.796 | Z17: =VALUE(LEFT(Y17,2)) -> 59 | AA17: =60-Y17 -> 0.204 | AB17: =60-ROUNDDOWN(Y17,0) -> 1 | AC17: =AB17-AA17 -> 0.796 | AD17: =AC17*60 -> 47.76
C18: 6 | E18: 6.000231 | F18: =E18-C18 -> 0.000231 | H18: 6 | I18: =K18*1000000 -> 27 | J18: 6.000027 | K18: =J18-H18 -> 2.7e-05 | L18: O | M18: 0.24996
C19: 6.5 | E19: 6.500232 | F19: =E19-C19 -> 0.000232 | L19: P | M19: 0.06237
C20: 7 | E20: 7.000196 | F20: =E20-C20 -> 0.000196 | L20: Q | M20: 0.1874
C21: 7.5 | E21: 7.500229 | F21: =E21-C21 -> 0.000229 | L21: R | M21: 0.24988
C22: 8 | E22: 8.000247 | F22: =E22-C22 -> 0.000247 | J22: =J12-J10 -> 1.000022 | L22: S | M22: 0.3749
C23: 8.5 | E23: 8.500239 | F23: =E23-C23 -> 0.000239 | J23: 0.999984 | L23: T | M23: 0.06248
C24: 9 | E24: 9.000251 | F24: =E24-C24 -> 0.000251 | J24: =J23-J22 -> -3.8e-05 | L24: U | M24: 0.12494
C25: 9.5 | E25: 9.500329 | F25: =E25-C25 -> 0.000329 | L25: V | M25: 0.18753
C26: 10 | E26: 10.000327 | F26: =E26-C26 -> 0.000327 | L26: W | M26: 0.0625
C27: 10.5 | E27: 10.500326 | F27: =E27-C27 -> 0.000326 | L27: Z | M27: 0.12497
C28: 11 | E28: 11.000338 | F28: =E28-C28 -> 0.000338
C29: 11.5 | E29: 11.500375 | F29: =E29-C29 -> 0.000375
C30: 12 | E30: 12.000372 | F30: =E30-C30 -> 0.000372
H32: Y Scale Interp
H33: known Col. Lookup (The value from the known column for which you want a corresponding unknown-other column value) | I33: Unknown. Column. result | J33: Ct of numbers< known column lookup in the known column. | K33: known column low | L33: known column high | M33: unknown col. Low | N33: unknown column high
H34: ='OC1000 Calibration'!E6 -> 0.1 | I34: =(H34-K34)/(L34-K34)*(N34-M34)+M34 -> 0.1000034 | J34: =COUNTIF($H$6:$H$18,"<"&H34) -> 1 | K34: =INDIRECT(ADDRESS(J34+5,8)) -> 0 | L34: =INDIRECT(ADDRESS(J34+6,8)) -> 0.5 | M34: =INDIRECT(ADDRESS(J34+5,10)) -> 0 | N34: =INDIRECT(ADDRESS(J34+6,10)) -> 0.500017
H35: ='OC1000 Calibration'!E7 -> 0.5 | I35: =(H35-K35)/(L35-K35)*(N35-M35)+M35 -> 0.500017 | J35: =COUNTIF($H$6:$H$18,"<"&H35) -> 1 | K35: =INDIRECT(ADDRESS(J35+5,8)) -> 0 | L35: =INDIRECT(ADDRESS(J35+6,8)) -> 0.5 | M35: =INDIRECT(ADDRESS(J35+5,10)) -> 0 | N35: =INDIRECT(ADDRESS(J35+6,10)) -> 0.500017
H36: ='OC1000 Calibration'!E8 -> 1 | I36: =(H36-K36)/(L36-K36)*(N36-M36)+M36 -> 1.000027 | J36: =COUNTIF($H$6:$H$18,"<"&H36) -> 2 | K36: =INDIRECT(ADDRESS(J36+5,8)) -> 0.5 | L36: =INDIRECT(ADDRESS(J36+6,8)) -> 1 | M36: =INDIRECT(ADDRESS(J36+5,10)) -> 0.500017 | N36: =INDIRECT(ADDRESS(J36+6,10)) -> 1.000027
H37: ='OC1000 Calibration'!E9 -> 1.5 | I37: =(H37-K37)/(L37-K37)*(N37-M37)+M37 -> 1.500024 | J37: =COUNTIF($H$6:$H$18,"<"&H37) -> 3 | K37: =INDIRECT(ADDRESS(J37+5,8)) -> 1 | L37: =INDIRECT(ADDRESS(J37+6,8)) -> 1.5 | M37: =INDIRECT(ADDRESS(J37+5,10)) -> 1.000027 | N37: =INDIRECT(ADDRESS(J37+6,10)) -> 1.500024
H38: ='OC1000 Calibration'!E10 -> 1.7 | I38: =(H38-K38)/(L38-K38)*(N38-M38)+M38 -> 1.7000312 | J38: =COUNTIF($H$6:$H$18,"<"&H38) -> 4 | K38: =INDIRECT(ADDRESS(J38+5,8)) -> 1.5 | L38: =INDIRECT(ADDRESS(J38+6,8)) -> 2 | M38: =INDIRECT(ADDRESS(J38+5,10)) -> 1.500024 | N38: =INDIRECT(ADDRESS(J38+6,10)) -> 2.000042
H39: ='OC1000 Calibration'!E11 -> 0 | I39: =(H39-K39)/(L39-K39)*(N39-M39)+M39 -> #VALUE! | J39: =COUNTIF($H$6:$H$18,"<"&H39) -> 0 | K39: =INDIRECT(ADDRESS(J39+5,8)) -> Nominal | L39: =INDIRECT(ADDRESS(J39+6,8)) -> 0 | M39: =INDIRECT(ADDRESS(J39+5,10)) -> Actual | N39: =INDIRECT(ADDRESS(J39+6,10)) -> 0
H40: ='OC1000 Calibration'!E12 -> 0 | I40: =(H40-K40)/(L40-K40)*(N40-M40)+M40 -> #VALUE! | J40: =COUNTIF($H$6:$H$18,"<"&H40) -> 0 | K40: =INDIRECT(ADDRESS(J40+5,8)) -> Nominal | L40: =INDIRECT(ADDRESS(J40+6,8)) -> 0 | M40: =INDIRECT(ADDRESS(J40+5,10)) -> Actual | N40: =INDIRECT(ADDRESS(J40+6,10)) -> 0
H41: ='OC1000 Calibration'!E13 -> 0 | I41: =(H41-K41)/(L41-K41)*(N41-M41)+M41 -> #VALUE! | J41: =COUNTIF($H$6:$H$18,"<"&H41) -> 0 | K41: =INDIRECT(ADDRESS(J41+5,8)) -> Nominal | L41: =INDIRECT(ADDRESS(J41+6,8)) -> 0 | M41: =INDIRECT(ADDRESS(J41+5,10)) -> Actual | N41: =INDIRECT(ADDRESS(J41+6,10)) -> 0
...

Sheet OC4000 Values
K1: Due Date | M1: =DATE(YEAR(M2)+3,MONTH(M2),DAY(M2)) -> 46713
F2: GAGE LINE RETICLE CERTIFICATION VALUES | K2: Calibration Date | M2: 45618
C3: OC4000 VALUES
C4: Top Inch Scale | H4: Vertical Inch Scale | L4: CIRCLES | M4: ACTUAL SIZE | O4: ANGLES | S4: Standard Counts | W4: minutes extracted | X4: Extraction | AC4: seconds extracted
C5: Nominal | D5: error (µ") | E5: Actual | H5: Nominal | I5: error (µ") | J5: Actual | L5: A | M5: 0.06222 | O5: Nominal | P5: ACTUAL VALUES | Q5: Dev. | S5: Deg | T5: Min | U5: Sec | V5: Std Counts | X5: Deg | Y5: Min | Z5: seconds extractor | AD5: Sec
C6: 0 | E6: 0 | F6: =E6-C6 -> 0 | H6: 0 | J6: =(I6*0.000001)+H6 -> 0 | K6: =J6-H6 -> 0 | L6: B | M6: 0.2497 | O6: 15 | P6: 14.998 | Q6: =P6-O6 -> -0.002 | S6: =X6 -> 14 | T6: =Z6 -> 59 | U6: =AD6 -> 52.8 | V6: =U6+(T6*60)+(S6*60*60) -> 53992.8 | W6: =O6-ROUNDDOWN(P6,0)+Q6 -> 0.998 | X6: =VALUE(LEFT(P6,2)) -> 14 | Y6: =W6*60 -> 59.88 | Z6: =VALUE(LEFT(Y6,2)) -> 59 | AA6: =60-Y6 -> 0.12 | AB6: =60-ROUNDDOWN(Y6,0) -> 1 | AC6: =AB6-AA6 -> 0.88 | AD6: =AC6*60 -> 52.8
C7: 0.5 | E7: 0.500056 | F7: =E7-C7 -> 5.6e-05 | H7: 0.5 | I7: =K7*1000000 -> 130 | J7: 0.50013 | K7: =J7-H7 -> 0.00013 | L7: C | M7: 0.6247 | O7: 30 | P7: 30.024 | Q7: =P7-O7 -> 0.024 | S7: =X7 -> 30 | T7: =Z7 -> 1 | U7: =AD7 -> 26.4 | V7: =U7+(T7*60)+(S7*60*60) -> 108086.4 | W7: =O7-ROUNDDOWN(P7,0)+Q7 -> 0.024 | X7: =VALUE(LEFT(P7,2)) -> 30 | Y7: =W7*60 -> 1.44 | Z7: =VALUE(LEFT(Y7,2)) -> 1 | AA7: =60-Y7 -> 58.56 | AB7: =60-ROUNDDOWN(Y7,0) -> 59 | AC7: =AB7-AA7 -> 0.44 | AD7: =AC7*60 -> 26.4
C8: 1 | E8: 1.000071 | F8: =E8-C8 -> 7.1e-05 | H8: 1 | I8: =K8*1000000 -> 20 | J8: 1.00002 | K8: =J8-H8 -> 2e-05 | L8: D | M8: 0.99969 | O8: 45 | P8: 45.0065 | Q8: =P8-O8 -> 0.0065 | S8: =X8 -> 45 | T8: =Z8 -> 0 | U8: =AD8 -> 23.4 | V8: =U8+(T8*60)+(S8*60*60) -> 162023.4 | W8: =O8-ROUNDDOWN(P8,0)+Q8 -> 0.0065 | X8: =VALUE(LEFT(P8,2)) -> 45 | Y8: =W8*60 -> 0.39 | Z8: =VALUE(LEFT(Y8,2)) -> 0 | AA8: =60-Y8 -> 59.61 | AB8: =60-ROUNDDOWN(Y8,0) -> 60 | AC8: =AB8-AA8 -> 0.39 | AD8: =AC8*60 -> 23.4
C9: 1.5 | E9: 1.500129 | F9: =E9-C9 -> 0.000129 | H9: 1.5 | I9: =K9*1000000 -> 200 | J9: 1.5002 | K9: =J9-H9 -> 0.0002 | L9: E | M9: 1.24968 | O9: 60 | P9: 59.9925 | Q9: =P9-O9 -> -0.0075 | S9: =X9 -> 59 | T9: =Z9 -> 59 | U9: =AD9 -> 33 | V9: =U9+(T9*60)+(S9*60*60) -> 215973 | W9: =O9-ROUNDDOWN(P9,0)+Q9 -> 0.9925 | X9: =VALUE(LEFT(P9,2)) -> 59 | Y9: =W9*60 -> 59.55 | Z9: =VALUE(LEFT(Y9,2)) -> 59 | AA9: =60-Y9 -> 0.45 | AB9: =60-ROUNDDOWN(Y9,0) -> 1 | AC9: =AB9-AA9 -> 0.55 | AD9: =AC9*60 -> 33
C10: 2 | E10: 2.000168 | F10: =E10-C10 -> 0.000168 | H10: 1.7 | I10: =K10*1000000 -> 140 | J10: 1.70014 | K10: =J10-H10 -> 0.00014 | L10: F | M10: 0.0622 | O10: 75 | P10: 74.999 | Q10: =P10-O10 -> -0.001 | S10: =X10 -> 74 | T10: =Z10 -> 59 | U10: =AD10 -> 56.4 | V10: =U10+(T10*60)+(S10*60*60) -> 269996.4 | W10: =O10-ROUNDDOWN(P10,0)+Q10 -> 0.999 | X10: =VALUE(LEFT(P10,2)) -> 74 | Y10: =W10*60 -> 59.94 | Z10: =VALUE(LEFT(Y10,2)) -> 59 | AA10: =60-Y10 -> 0.06 | AB10: =60-ROUNDDOWN(Y10,0) -> 1 | AC10: =AB10-AA10 -> 0.94 | AD10: =AC10*60 -> 56.4
C11: 2.5 | E11: 2.500168 | F11: =E11-C11 -> 0.000168 | I11: =K11*1000000 -> 0 | K11: =J11-H11 -> 0 | L11: G | M11: 0.18719 | O11: 90 | P11: 89.9943 | Q11: =P11-O11 -> -0.0057 | S11: =X11 -> 89 | T11: =Z11 -> 59 | U11: =AD11 -> 39.48 | V11: =U11+(T11*60)+(S11*60*60) -> 323979.48 | W11: =O11-ROUNDDOWN(P11,0)+Q11 -> 0.9943 | X11: =VALUE(LEFT(P11,2)) -> 89 | Y11: =W11*60 -> 59.658 | Z11: =VALUE(LEFT(Y11,2)) -> 59 | AA11: =60-Y11 -> 0.342 | AB11: =60-ROUNDDOWN(Y11,0) -> 1 | AC11: =AB11-AA11 -> 0.658 | AD11: =AC11*60 -> 39.48
C12: 3 | E12: 3.000206 | F12: =E12-C12 -> 0.000206 | I12: =K12*1000000 -> 0 | K12: =J12-H12 -> 0 | L12: H | M12: 0.2469 | O12: 105 | P12: 104.9965 | Q12: =P12-O12 -> -0.0035 | S12: =X12 -> 104 | T12: =Z12 -> 59 | U12: =AD12 -> 47.4 | V12: =U12+(T12*60)+(S12*60*60) -> 377987.4 | W12: =O12-ROUNDDOWN(P12,0)+Q12 -> 0.9965 | X12: =VALUE(LEFT(P12,3)) -> 104 | Y12: =W12*60 -> 59.79 | Z12: =VALUE(LEFT(Y12,2)) -> 59 | AA12: =60-Y12 -> 0.21 | AB12: =60-ROUNDDOWN(Y12,0) -> 1 | AC12: =AB12-AA12 -> 0.79 | AD12: =AC12*60 -> 47.4
C13: 3.5 | E13: 3.500261 | F13: =E13-C13 -> 0.000261 | I13: =K13*1000000 -> 0 | K13: =J13-H13 -> 0 | L13: J | M13: 0.4372 | O13: 120 | P13: 120.0084 | Q13: =P13-O13 -> 0.0084 | S13: =X13 -> 120 | T13: =Z13 -> 0 | U13: =AD13 -> 30.24 | V13: =U13+(T13*60)+(S13*60*60) -> 432030.24 | W13: =O13-ROUNDDOWN(P13,0)+Q13 -> 0.0084 | X13: =VALUE(LEFT(P13,3)) -> 120 | Y13: =W13*60 -> 0.504 | Z13: =VALUE(LEFT(Y13,2)) -> 0 | AA13: =60-Y13 -> 59.496 | AB13: =60-ROUNDDOWN(Y13,0) -> 60 | AC13: =AB13-AA13 -> 0.504 | AD13: =AC13*60 -> 30.24
C14: 4 | E14: 4.000273 | F14: =E14-C14 -> 0.000273 | I14: =K14*1000000 -> 0 | K14: =J14-H14 -> 0 | L14: K | M14: 0.62471 | O14: 135 | P14: 134.9934 | Q14: =P14-O14 -> -0.0066 | S14: =X14 -> 134 | T14: =Z14 -> 59 | U14: =AD14 -> 36.24 | V14: =U14+(T14*60)+(S14*60*60) -> 485976.24 | W14: =O14-ROUNDDOWN(P14,0)+Q14 -> 0.9934 | X14: =VALUE(LEFT(P14,3)) -> 134 | Y14: =W14*60 -> 59.604 | Z14: =VALUE(LEFT(Y14,2)) -> 59 | AA14: =60-Y14 -> 0.396 | AB14: =60-ROUNDDOWN(Y14,0) -> 1 | AC14: =AB14-AA14 -> 0.604 | AD14: =AC14*60 -> 36.24
C15: 4.5 | E15: 4.500303 | F15: =E15-C15 -> 0.000303 | I15: =K15*1000000 -> 0 | K15: =J15-H15 -> 0 | L15: L | M15: 0.06226 | O15: 150 | P15: 150.0028 | Q15: =P15-O15 -> 0.0028 | S15: =X15 -> 150 | T15: =Z15 -> 0 | U15: =AD15 -> 10.08 | V15: =U15+(T15*60)+(S15*60*60) -> 540010.08 | W15: =O15-ROUNDDOWN(P15,0)+Q15 -> 0.0028 | X15: =VALUE(LEFT(P15,3)) -> 150 | Y15: =W15*60 -> 0.168 | Z15: =VALUE(LEFT(Y15,2)) -> 0 | AA15: =60-Y15 -> 59.832 | AB15: =60-ROUNDDOWN(Y15,0) -> 60 | AC15: =AB15-AA15 -> 0.168 | AD15: =AC15*60 -> 10.08
C16: 5 | E16: 5.000301 | F16: =E16-C16 -> 0.000301 | I16: =K16*1000000 -> 0 | K16: =J16-H16 -> 0 | L16: M | M16: 0.12474 | O16: 165 | P16: 165.0062 | Q16: =P16-O16 -> 0.0062 | S16: =X16 -> 165 | T16: =Z16 -> 0 | U16: =AD16 -> 22.32 | V16: =U16+(T16*60)+(S16*60*60) -> 594022.32 | W16: =O16-ROUNDDOWN(P16,0)+Q16 -> 0.0062 | X16: =VALUE(LEFT(P16,3)) -> 165 | Y16: =W16*60 -> 0.372 | Z16: =VALUE(LEFT(Y16,2)) -> 0 | AA16: =60-Y16 -> 59.628 | AB16: =60-ROUNDDOWN(Y16,0) -> 60 | AC16: =AB16-AA16 -> 0.372 | AD16: =AC16*60 -> 22.32
C17: 5.5 | E17: 5.500326 | F17: =E17-C17 -> 0.000326 | I17: =K17*1000000 -> 0 | K17: =J17-H17 -> 0 | L17: N | M17: 0.18724 | O17: 180 | P17: 179.9951 | Q17: =P17-O17 -> -0.0049 | S17: =X17 -> 179 | T17: =Z17 -> 59 | U17: =AD17 -> 42.36 | V17: =U17+(T17*60)+(S17*60*60) -> 647982.36 | W17: =O17-ROUNDDOWN(P17,0)+Q17 -> 0.9951 | X17: =VALUE(LEFT(P17,3)) -> 179 | Y17: =W17*60 -> 59.706 | Z17: =VALUE(LEFT(Y17,2)) -> 59 | AA17: =60-Y17 -> 0.294 | AB17: =60-ROUNDDOWN(Y17,0) -> 1 | AC17: =AB17-AA17 -> 0.706 | AD17: =AC17*60 -> 42.36
C18: 6 | E18: 6.000349 | F18: =E18-C18 -> 0.000349 | I18: =K18*1000000 -> 0 | K18: =J18-H18 -> 0 | L18: O | M18: 0.24974
C19: 6.5 | E19: 6.500349 | F19: =E19-C19 -> 0.000349 | L19: P | M19: 0.06227
C20: 7 | E20: 7.000361 | F20: =E20-C20 -> 0.000361 | L20: Q | M20: 0.18724
C21: 7.5 | E21: 7.500377 | F21: =E21-C21 -> 0.000377 | L21: R | M21: 0.24974
C22: 8 | E22: 8.000386 | F22: =E22-C22 -> 0.000386 | J22: =J12-J10 -> -1.70014 | L22: S | M22: 0.37475
C23: 8.5 | E23: 8.500415 | F23: =E23-C23 -> 0.000415 | J23: 0.999984 | L23: T | M23: 0.06226
C24: 9 | E24: 9.000439 | F24: =E24-C24 -> 0.000439 | J24: =J23-J22 -> 2.700124 | L24: U | M24: 0.12474
C25: 9.5 | E25: 9.500481 | F25: =E25-C25 -> 0.000481 | L25: V | M25: 0.18724
C26: 10 | E26: 10.000477 | F26: =E26-C26 -> 0.000477 | L26: W | M26: 0.06232
C27: 10.5 | E27: 10.500535 | F27: =E27-C27 -> 0.000535 | L27: Z | M27: 0.12483
C28: 11 | E28: 11.000537 | F28: =E28-C28 -> 0.000537
C29: 11.5 | E29: 11.500573 | F29: =E29-C29 -> 0.000573
C30: 12 | E30: 12.000619 | F30: =E30-C30 -> 0.000619
H32: Y Scale Interp
H33: known Col. Lookup (The value from the known column for which you want a corresponding unknown-other column value) | I33: Unknown. Column. result | J33: Ct of numbers< known column lookup in the known column. | K33: known column low | L33: known column high | M33: unknown col. Low | N33: unknown column high
H34: ='OC1000 Calibration'!E6 -> 0.1 | I34: =(H34-K34)/(L34-K34)*(N34-M34)+M34 -> 0.100026 | J34: =COUNTIF($H$6:$H$18,"<"&H34) -> 1 | K34: =INDIRECT(ADDRESS(J34+5,8)) -> 0 | L34: =INDIRECT(ADDRESS(J34+6,8)) -> 0.5 | M34: =INDIRECT(ADDRESS(J34+5,10)) -> 0 | N34: =INDIRECT(ADDRESS(J34+6,10)) -> 0.50013
H35: ='OC1000 Calibration'!E7 -> 0.5 | I35: =(H35-K35)/(L35-K35)*(N35-M35)+M35 -> 0.50013 | J35: =COUNTIF($H$6:$H$18,"<"&H35) -> 1 | K35: =INDIRECT(ADDRESS(J35+5,8)) -> 0 | L35: =INDIRECT(ADDRESS(J35+6,8)) -> 0.5 | M35: =INDIRECT(ADDRESS(J35+5,10)) -> 0 | N35: =INDIRECT(ADDRESS(J35+6,10)) -> 0.50013
H36: ='OC1000 Calibration'!E8 -> 1 | I36: =(H36-K36)/(L36-K36)*(N36-M36)+M36 -> 1.00002 | J36: =COUNTIF($H$6:$H$18,"<"&H36) -> 2 | K36: =INDIRECT(ADDRESS(J36+5,8)) -> 0.5 | L36: =INDIRECT(ADDRESS(J36+6,8)) -> 1 | M36: =INDIRECT(ADDRESS(J36+5,10)) -> 0.50013 | N36: =INDIRECT(ADDRESS(J36+6,10)) -> 1.00002
H37: ='OC1000 Calibration'!E9 -> 1.5 | I37: =(H37-K37)/(L37-K37)*(N37-M37)+M37 -> 1.5002 | J37: =COUNTIF($H$6:$H$18,"<"&H37) -> 3 | K37: =INDIRECT(ADDRESS(J37+5,8)) -> 1 | L37: =INDIRECT(ADDRESS(J37+6,8)) -> 1.5 | M37: =INDIRECT(ADDRESS(J37+5,10)) -> 1.00002 | N37: =INDIRECT(ADDRESS(J37+6,10)) -> 1.5002
H38: ='OC1000 Calibration'!E10 -> 1.7 | I38: =(H38-K38)/(L38-K38)*(N38-M38)+M38 -> 1.70014 | J38: =COUNTIF($H$6:$H$18,"<"&H38) -> 4 | K38: =INDIRECT(ADDRESS(J38+5,8)) -> 1.5 | L38: =INDIRECT(ADDRESS(J38+6,8)) -> 1.7 | M38: =INDIRECT(ADDRESS(J38+5,10)) -> 1.5002 | N38: =INDIRECT(ADDRESS(J38+6,10)) -> 1.70014
H39: ='OC1000 Calibration'!E11 -> 0 | I39: =(H39-K39)/(L39-K39)*(N39-M39)+M39 -> #VALUE! | J39: =COUNTIF($H$6:$H$18,"<"&H39) -> 0 | K39: =INDIRECT(ADDRESS(J39+5,8)) -> Nominal | L39: =INDIRECT(ADDRESS(J39+6,8)) -> 0 | M39: =INDIRECT(ADDRESS(J39+5,10)) -> Actual | N39: =INDIRECT(ADDRESS(J39+6,10)) -> 0
H40: ='OC1000 Calibration'!E12 -> 0 | I40: =(H40-K40)/(L40-K40)*(N40-M40)+M40 -> #VALUE! | J40: =COUNTIF($H$6:$H$18,"<"&H40) -> 0 | K40: =INDIRECT(ADDRESS(J40+5,8)) -> Nominal | L40: =INDIRECT(ADDRESS(J40+6,8)) -> 0 | M40: =INDIRECT(ADDRESS(J40+5,10)) -> Actual | N40: =INDIRECT(ADDRESS(J40+6,10)) -> 0
H41: ='OC1000 Calibration'!E13 -> 0 | I41: =(H41-K41)/(L41-K41)*(N41-M41)+M41 -> #VALUE! | J41: =COUNTIF($H$6:$H$18,"<"&H41) -> 0 | K41: =INDIRECT(ADDRESS(J41+5,8)) -> Nominal | L41: =INDIRECT(ADDRESS(J41+6,8)) -> 0 | M41: =INDIRECT(ADDRESS(J41+5,10)) -> Actual | N41: =INDIRECT(ADDRESS(J41+6,10)) -> 0
...

Sheet Vaidation Log
A1: Date: | B1: Action:
A2: 42074 | B2: Lookup Corrections verified, Magnification function verified, Password protection added
A3: 42172 | B3: OC2000 values added, programmed. Fillable cells identified by color code. Worksheet renamed "Optical Comparator Worksheet"
A4: 42013 | B4: Magscale recalibrated, Mag accuracy deviation and tolerance calculation was corrected. Deviations calculated for angles, Visual improvements, Summary of results page added
A5: 42388 | B5: Corrected a Y axis formula error
A6: 42773 | B6: Removed Table aligmnent fields
A7: 43309 | B7: Added OC3000, made start point for x and y axis adjustable
A8: 44396 | B8: Updated reference values, no software changes
A9: 45446 | B9: Updated reference values, updated OC3000 standard entry format
A10: 45476 | B10: added decimal degrees deviation
A11: 45967 | B11: fixed a calculation error in the minutes and seconds extraction of the OC3000 and OC4000 tabs (angle)

Sheet OC1000 Values
F2: OC1000 Cert Values
C3: OC1000 VALUES | F3: =
C4: Top Inch Scale | H4: Vertical Inch Scale | L4: CIRCLES | M4: ACTUAL SIZE | O4: ANGLES | S4: Standard Counts
C5: Nominal | D5: error (µ") | E5: Actual | H5: Nominal | I5: error (µ") | J5: Actual | L5: A | O5: Nominal | P5: ACTUAL VALUES | Q5: Dev. | S5: Deg | T5: Min | U5: Sec | V5: Std Counts
C6: 0 | E6: =(D6*0.000001)+C6 -> 0 | F6: =E6-C6 -> 0 | H6: 0 | J6: =(I6*0.000001)+H6 -> 0 | K6: =J6-H6 -> 0 | L6: B | M6: 0.25001 | O6: 15 | P6: 14° 59' 52" | Q6: +5" | S6: 14 | T6: 59 | U6: 52 | V6: =U6+(T6*60)+(S6*60*60) -> 53992
C7: 0.5 | D7: 63 | E7: =(D7*0.000001)+C7 -> 0.500063 | F7: ='OC4000 Values'!G10 -> 0 | H7: 0.2 | I7: 1 | J7: =(I7*0.000001)+H7 -> 0.200001 | K7: =J7-H7 -> 1e-06 | L7: C | M7: 0.62503 | O7: 30 | Q7: -40" | V7: =U7+(T7*60)+(S7*60*60) -> 0
C8: 1 | D8: 134 | E8: =(D8*0.000001)+C8 -> 1.000134 | F8: ='OC4000 Values'!G11 -> 0 | H8: 0.4 | I8: 14 | J8: =(I8*0.000001)+H8 -> 0.400014 | K8: =J8-H8 -> 1.4e-05 | L8: D | O8: 45 | Q8: +9" | V8: =U8+(T8*60)+(S8*60*60) -> 0
C9: 1.5 | D9: 171 | E9: =(D9*0.000001)+C9 -> 1.500171 | F9: ='OC4000 Values'!G12 -> 0 | H9: 0.6 | I9: 19 | J9: =(I9*0.000001)+H9 -> 0.600019 | K9: =J9-H9 -> 1.9e-05 | L9: E | O9: 60 | Q9: +34" | V9: =U9+(T9*60)+(S9*60*60) -> 0
C10: 2 | D10: 213 | E10: =(D10*0.000001)+C10 -> 2.000213 | F10: ='OC4000 Values'!G13 -> 0 | H10: 0.8 | I10: 36 | J10: =(I10*0.000001)+H10 -> 0.800036 | K10: =J10-H10 -> 3.6e-05 | L10: F | M10: 0.06253 | O10: 75 | Q10: -39" | V10: =U10+(T10*60)+(S10*60*60) -> 0
C11: 2.5 | D11: 251 | E11: =(D11*0.000001)+C11 -> 2.500251 | H11: 1 | I11: 31 | J11: =(I11*0.000001)+H11 -> 1.000031 | K11: =J11-H11 -> 3.1e-05 | L11: G | O11: 90 | P11: 90° 0' 04" | Q11: -1' 8" | S11: 90 | T11: 0 | U11: 4 | V11: =U11+(T11*60)+(S11*60*60) -> 324004
C12: 3 | D12: 293 | E12: =(D12*0.000001)+C12 -> 3.000293 | F12: ='OC4000 Values'!G14 -> 0 | H12: 1.1 | I12: 40 | J12: =(I12*0.000001)+H12 -> 1.10004 | K12: =J12-H12 -> 4e-05 | L12: H | M12: 0.25003 | O12: 105 | Q12: -59" | V12: =U12+(T12*60)+(S12*60*60) -> 0
C13: 3.5 | D13: 319 | E13: =(D13*0.000001)+C13 -> 3.500319 | H13: 1.2 | I13: 39 | J13: =(I13*0.000001)+H13 -> 1.200039 | K13: =J13-H13 -> 3.9e-05 | L13: J | O13: 120 | Q13: -49" | V13: =U13+(T13*60)+(S13*60*60) -> 0
C14: 4 | D14: 339 | E14: =(D14*0.000001)+C14 -> 4.000339 | F14: ='OC4000 Values'!G15 -> 0 | H14: 1.3 | I14: 30 | J14: =(I14*0.000001)+H14 -> 1.30003 | K14: =J14-H14 -> 3e-05 | L14: K | O14: 135 | P14: 135° 0' 25" | Q14: -11" | S14: 135 | T14: 0 | U14: 25 | V14: =U14+(T14*60)+(S14*60*60) -> 486025
C15: 4.5 | D15: 409 | E15: =(D15*0.000001)+C15 -> 4.500409 | H15: 1.4 | I15: 39 | J15: =(I15*0.000001)+H15 -> 1.400039 | K15: =J15-H15 -> 3.9e-05 | L15: L | O15: 150 | Q15: -1' 21" | V15: =U15+(T15*60)+(S15*60*60) -> 0
C16: 5 | D16: 425 | E16: =(D16*0.000001)+C16 -> 5.000425 | F16: ='OC4000 Values'!G16 -> 0 | H16: 1.5 | I16: 45 | J16: =(I16*0.000001)+H16 -> 1.500045 | K16: =J16-H16 -> 4.5e-05 | L16: M | O16: 165 | Q16: -48" | V16: =U16+(T16*60)+(S16*60*60) -> 0
C17: 5.5 | D17: 458 | E17: =(D17*0.000001)+C17 -> 5.500458 | H17: 1.6 | I17: 43 | J17: =(I17*0.000001)+H17 -> 1.600043 | K17: =J17-H17 -> 4.3e-05 | L17: N | O17: 180 | Q17: -26" | V17: =U17+(T17*60)+(S17*60*60) -> 0
C18: 6 | D18: 449 | E18: =(D18*0.000001)+C18 -> 6.000449 | F18: ='OC4000 Values'!G17 -> 0 | H18: 1.7 | I18: 43 | J18: =(I18*0.000001)+H18 -> 1.700043 | K18: =J18-H18 -> 4.3e-05 | L18: O
C19: 6.5 | D19: 467 | E19: =(D19*0.000001)+C19 -> 6.500467 | L19: P
C20: 7 | D20: 465 | E20: =(D20*0.000001)+C20 -> 7.000465 | F20: ='OC4000 Values'!G18 -> 0 | L20: Q
C21: 7.5 | D21: 475 | E21: =(D21*0.000001)+C21 -> 7.500475 | L21: R
C22: 8 | D22: 513 | E22: =(D22*0.000001)+C22 -> 8.000513 | F22: ='OC4000 Values'!G19 -> 0 | L22: S
C23: 8.5 | L23: T
C24: 9 | F24: ='OC4000 Values'!G20 -> 0 | L24: U
C25: 9.5 | L25: V
C26: 10 | F26: ='OC4000 Values'!G21 -> 0 | L26: W
C27: 10.5 | L27: Z
C28: 11 | F28: ='OC4000 Values'!G22 -> 0
C29: 11.5
C30: 12 | F30: ='OC4000 Values'!G23 -> 0

Sheet OC1000 Calibration
B1: Standardization of OC | O1: OC1000 Values
B2: Master Scale Used:
B3: Date: | H3: A,B,C,G,J,K
B4: X axis | E4: Y Axis | H4: Angles | O4: X axis | S4: Y Axis | V4: Angles
B5: Nominal | C5: indicated | D5: True Error | E5: Nominal | F5: indicated | G5: True Error | H5: Nominal | I5: Deg | J5: Min | K5: Sec | L5: Cts | M5: Std | O5: Nominal | P5: Indicated | Q5: True Error | S5: Nominal | T5: Indicated | U5: True Error | V5: =H5 -> Nominal | W5: =I5 -> Deg | X5: =J5 -> Min | Y5: =K5 -> Sec | Z5: =L5 -> Cts | AA5: True Rdg | AB5: Deg | AC5: Min | AD5: Sec
B6: 0.5 | C6: 0.500013 | D6: =((C6-B6)-'OC3000 Values'!F7) -> -1e-06 | E6: 0.1 | F6: 0.09995 | G6: =((F6-E6)-'OC3000 Values'!I34) -> -0.1000534 | H6: 15 | I6: 15 | J6: 0 | K6: 37 | L6: =K6+(J6*60)+(I6*60*60) -> 54037 | M6: ='OC3000 Values'!V6 -> 53996.04 | O6: 0.5 | P6: 0.50004 | Q6: =(P6-O6)-D6 -> 4.1e-05 | S6: =E6 -> 0.1 | T6: 0.09999 | U6: =(T6-S6)-G6 -> 0.1000434 | V6: =H6 -> 15 | W6: 15 | X6: 0 | Y6: 56 | Z6: =Y6+(X6*60)+(W6*60*60) -> 54056 | AA6: =Z6-(L6-M6) -> 54015.04
B7: 1 | C7: 1.000054 | D7: =((C7-B7)-'OC3000 Values'!F8) -> 0 | E7: 0.5 | F7: 0.49991 | G7: =((F7-E7)-'OC3000 Values'!I35) -> -0.500107 | H7: 30 | I7: 30 | J7: 0 | K7: 32 | L7: =K7+(J7*60)+(I7*60*60) -> 108032 | M7: ='OC3000 Values'!V7 -> 107988.12 | O7: 1 | P7: 1.00008 | Q7: =(P7-O7)-D7 -> 8e-05 | S7: =E7 -> 0.5 | T7: 0.49995 | U7: =(T7-S7)-G7 -> 0.500057 | V7: =H7 -> 30 | W7: 30 | X7: 0 | Y7: 30 | Z7: =Y7+(X7*60)+(W7*60*60) -> 108030 | AA7: =Z7-(L7-M7) -> 107986.12
B8: 1.5 | C8: 1.500084 | D8: =((C8-B8)-'OC3000 Values'!F9) -> 0 | E8: 1 | F8: 0.99989 | G8: =((F8-E8)-'OC3000 Values'!I36) -> -1.000137 | H8: 90 | I8: 90 | J8: 0 | K8: 51 | L8: =K8+(J8*60)+(I8*60*60) -> 324051 | M8: ='OC3000 Values'!V11 -> 323998.56 | O8: 1.5 | P8: 1.50005 | Q8: =(P8-O8)-D8 -> 5e-05 | S8: =E8 -> 1 | T8: 0.99993 | U8: =(T8-S8)-G8 -> 1.000067 | V8: =H8 -> 90 | W8: 90 | X8: 0 | Y8: 53 | Z8: =Y8+(X8*60)+(W8*60*60) -> 324053 | AA8: =Z8-(L8-M8) -> 324000.56
B9: 2 | C9: 2.000087 | D9: =((C9-B9)-'OC3000 Values'!F10) -> 1.5e-05 | E9: 1.5 | F9: 1.49995 | G9: =((F9-E9)-'OC3000 Values'!I37) -> -1.500074 | H9: 135 | I9: 135 | J9: 1 | K9: 8 | L9: =K9+(J9*60)+(I9*60*60) -> 486068 | M9: ='OC3000 Values'!V14 -> 485991 | O9: 2 | P9: 2.00013 | Q9: =(P9-O9)-D9 -> 0.000115 | S9: =E9 -> 1.5 | T9: 1.49995 | U9: =(T9-S9)-G9 -> 1.500024 | V9: =H9 -> 135 | W9: 135 | X9: 2 | Y9: 4 | Z9: =Y9+(X9*60)+(W9*60*60) -> 486124 | AA9: =Z9-(L9-M9) -> 486047
B10: 2.5 | C10: 2.500132 | D10: =((C10-B10)-'OC3000 Values'!F11) -> 1.6e-05 | E10: 1.7 | F10: 1.69997 | G10: =((F10-E10)-'OC3000 Values'!I38) -> -1.7000612 | H10: 150 | I10: 150 | J10: 0 | K10: 49 | L10: =K10+(J10*60)+(I10*60*60) -> 540049 | M10: ='OC3000 Values'!V15 -> 539995.68 | O10: 2.5 | P10: 2.50009 | Q10: =(P10-O10)-D10 -> 7.4e-05 | S10: =E10 -> 1.7 | T10: 1.70005 | U10: =(T10-S10)-G10 -> 1.7001112 | V10: =H10 -> 150 | W10: 150 | X10: 1 | Y10: 11 | Z10: =Y10+(X10*60)+(W10*60*60) -> 540071 | AA10: =Z10-(L10-M10) -> 540017.68
B11: 3 | C11: 3.000165 | D11: =((C11-B11)-'OC3000 Values'!F12) -> 7e-06 | G11: =((F11-E11)-'OC3000 Values'!I39) -> #VALUE! | O11: 3 | P11: 3.00017 | Q11: =(P11-O11)-D11 -> 0.000163 | S11: =E11 -> 0 | U11: =(T11-S11)-G11 -> #VALUE! | V11: =H11 -> 0 | AA11: =Z11-(L11-M11) -> 0
B12: 3.5 | C12: 3.500176 | D12: =((C12-B12)-'OC3000 Values'!F13) -> 2e-05 | G12: =((F12-E12)-'OC3000 Values'!I40) -> #VALUE! | O12: 3.5 | P12: 3.50018 | Q12: =(P12-O12)-D12 -> 0.00016 | S12: =E12 -> 0 | U12: =(T12-S12)-G12 -> #VALUE! | V12: =H12 -> 0 | AA12: =Z12-(L12-M12) -> 0
B13: 4 | C13: 4.000196 | D13: =((C13-B13)-'OC3000 Values'!F14) -> 5e-06 | G13: =((F13-E13)-'OC3000 Values'!I41) -> #VALUE! | O13: 4 | P13: 4.00022 | Q13: =(P13-O13)-D13 -> 0.000215 | S13: =E13 -> 0 | U13: =(T13-S13)-G13 -> #VALUE! | V13: =H13 -> 0 | AA13: =Z13-(L13-M13) -> 0
B14: 4.5 | C14: 4.500232 | D14: =((C14-B14)-'OC3000 Values'!F15) -> 1.7e-05 | G14: =((F14-E14)-'OC3000 Values'!I42) -> #VALUE! | O14: 4.5 | P14: 4.5003 | Q14: =(P14-O14)-D14 -> 0.000283 | S14: =E14 -> 0 | U14: =(T14-S14)-G14 -> #VALUE! | V14: =H14 -> 0 | AA14: =Z14-(L14-M14) -> 0
B15: 5 | C15: 5.000235 | D15: =((C15-B15)-'OC3000 Values'!F16) -> 4.1e-05 | G15: =((F15-E15)-'OC3000 Values'!I43) -> #VALUE! | O15: 5 | P15: 5.0003 | Q15: =(P15-O15)-D15 -> 0.000259 | S15: =E15 -> 0 | U15: =(T15-S15)-G15 -> #VALUE! | V15: =H15 -> 0 | AA15: =Z15-(L15-M15) -> 0
B16: 5.5 | C16: 5.500234 | D16: =((C16-B16)-'OC3000 Values'!F17) -> 2.1e-05 | G16: =((F16-E16)-'OC3000 Values'!I44) -> #VALUE! | O16: 5.5 | P16: 5.50035 | Q16: =(P16-O16)-D16 -> 0.000329 | S16: =E16 -> 0 | U16: =(T16-S16)-G16 -> #VALUE! | V16: =H16 -> 0 | AA16: =Z16-(L16-M16) -> 0
B17: 6 | C17: 6.00027 | D17: =((C17-B17)-'OC3000 Values'!F18) -> 3.9e-05 | G17: =((F17-E17)-'OC3000 Values'!I45) -> #VALUE! | O17: 6 | P17: 6.00043 | Q17: =(P17-O17)-D17 -> 0.000391 | S17: =E17 -> 0 | U17: =(T17-S17)-G17 -> #VALUE! | V17: =H17 -> 0 | AA17: =Z17-(L17-M17) -> 0
B18: 6.5 | C18: 6.50027 | D18: =((C18-B18)-'OC3000 Values'!F19) -> 3.8e-05 | G18: =((F18-E18)-'OC3000 Values'!I46) -> #VALUE! | O18: 6.5 | P18: 6.50043 | Q18: =(P18-O18)-D18 -> 0.000392 | S18: =E18 -> 0 | U18: =(T18-S18)-G18 -> #VALUE!
B19: 7 | C19: 7.000244 | D19: =((C19-B19)-'OC3000 Values'!F20) -> 4.8e-05 | G19: =((F19-E19)-'OC3000 Values'!I47) -> #VALUE! | J19: Mag Circles | O19: 7 | P19: 7.00043 | Q19: =(P19-O19)-D19 -> 0.000382 | S19: =E19 -> 0 | U19: =(T19-S19)-G19 -> #VALUE! | X19: Mag Circles
B20: 7.5 | C20: 7.500276 | D20: =((C20-B20)-'OC3000 Values'!F21) -> 4.7e-05 | I20: Circle | J20: Nominal | K20: indicated | L20: True Error | O20: 7.5 | P20: 7.50048 | Q20: =(P20-O20)-D20 -> 0.000433 | W20: Circle | X20: Nominal | Y20: Indicated | Z20: True Error
B21: 8 | C21: 8.000264 | D21: =((C21-B21)-'OC3000 Values'!F22) -> 1.7e-05 | I21: A | N21: reset at 7 | O21: 8 | P21: 8.00052 | Q21: =(P21-O21)-D21 -> 0.000503 | W21: A
B22: 8.5 | I22: B | N22: 7.50048 | O22: 8.5 | P22: 8.50048 | Q22: =(P22-O22)-D20 -> 0.000433 | W22: B
B23: 9 | I23: C | N23: 8.00048 | O23: 9 | P23: 9.00048 | Q23: =(P23-O23)-D21 -> 0.000463 | W23: C
B24: 9.5 | I24: D | W24: D
B25: 10 | I25: E | W25: E
B26: 10.5 | I26: F | W26: F
B27: 11 | I27: G | W27: G
B28: 11.5 | I28: H | W28: H
B29: 12 | I29: I | W29: I
I30: J | W30: J
I31: K | W31: K
I32: L | W32: L
I33: M | W33: M
I34: N | W34: N
I35: O | W35: O

Sheet OC100A Results 2019
C1: Magnification Scale Calibration Values
C2: =Worksheet!E29 -> 10 | D2: X setting | E2: Cal. Date: | F2: 42377 | I2: Interpolated correction factors for Normal Use
I3: known Col. Lookup (The value from the known column for which you want a corresponding unknown-other column value) | J3: Unknown. Column. result | K3: Ct of numbers< known column lookup in the known column. | L3: known column low | M3: known column high | N3: unknown col. Low | O3: unknown column high | P3: Actual Result | R3: Comparator Characterization
C4: Marked | D4: Nominal | E4: indicated | F4: Error | G4: Cal. Corr. Factor | H4: Usage Corr. Factor | I4: =Worksheet!F32 -> 0 | J4: =(I4-L4)/(M4-L4)*(O4-N4)+N4 -> #VALUE! | K4: =COUNTIF($C$5:$C$25,"<"&I4) -> 0 | L4: =INDIRECT(ADDRESS(K4+4,3)) -> Marked | M4: =INDIRECT(ADDRESS(K4+5,3)) -> 0 | N4: =INDIRECT(ADDRESS(K4+4,8)) -> Usage Corr. Factor | O4: =INDIRECT(ADDRESS(K4+5,8)) -> 0 | P4: =I4+J4 -> #VALUE! | R4: Nominal | S4: Indicated | T4: Correction from OC2000 | U4: Corrected Value | V4: Characterized Correction
C5: =D5/$C$2 -> 0 | D5: 0 | E5: 0 | F5: =E5-D5 -> 0 | I5: =Worksheet!F33 -> 0 | J5: =(I5-L5)/(M5-L5)*(O5-N5)+N5 -> #VALUE! | K5: =COUNTIF($C$5:$C$25,"<"&I5) -> 0 | L5: =INDIRECT(ADDRESS(K5+4,3)) -> Marked | M5: =INDIRECT(ADDRESS(K5+5,3)) -> 0 | N5: =INDIRECT(ADDRESS(K5+4,5)) -> indicated | O5: =INDIRECT(ADDRESS(K5+5,5)) -> 0 | R5: 0 | S5: 0 | T5: 0 | U5: 0
C6: =D6/$C$2 -> 0.02 | D6: 0.2 | F6: =E6-D6 -> -0.2 | G6: =J19 -> -1.04e-05 | H6: =-(F6+G6) -> 0.2000104 | I6: =Worksheet!F34 -> 0 | J6: =(I6-L6)/(M6-L6)*(O6-N6)+N6 -> #VALUE! | K6: =COUNTIF($C$5:$C$25,"<"&I6) -> 0 | L6: =INDIRECT(ADDRESS(K6+4,3)) -> Marked | M6: =INDIRECT(ADDRESS(K6+5,3)) -> 0 | N6: =INDIRECT(ADDRESS(K6+4,5)) -> indicated | O6: =INDIRECT(ADDRESS(K6+5,5)) -> 0 | R6: 0.5 | S6: 0.50004 | T6: =-'OC3000 Values'!F7 -> -1.4e-05 | U6: =S6+T6 -> 0.500026 | V6: =R6-U6 -> -2.6e-05
C7: =D7/$C$2 -> 0.04 | D7: 0.4 | F7: =E7-D7 -> -0.4 | G7: =J20 -> -2.08e-05 | H7: =-(F7+G7) -> 0.4000208 | I7: =Worksheet!F35 -> 0 | J7: =(I7-L7)/(M7-L7)*(O7-N7)+N7 -> #VALUE! | K7: =COUNTIF($C$5:$C$25,"<"&I7) -> 0 | L7: =INDIRECT(ADDRESS(K7+4,3)) -> Marked | M7: =INDIRECT(ADDRESS(K7+5,3)) -> 0 | N7: =INDIRECT(ADDRESS(K7+4,5)) -> indicated | O7: =INDIRECT(ADDRESS(K7+5,5)) -> 0 | R7: 1 | S7: 1.00001 | T7: =-'OC3000 Values'!F8 -> -5.4e-05 | U7: =S7+T7 -> 0.999956 | V7: =R7-U7 -> 4.4e-05
C8: =D8/$C$2 -> 0.06 | D8: 0.6 | F8: =E8-D8 -> -0.6 | G8: =J21 -> -1.2e-05 | H8: =-(F8+G8) -> 0.600012 | I8: =Worksheet!F36 -> 0 | J8: =(I8-L8)/(M8-L8)*(O8-N8)+N8 -> #VALUE! | K8: =COUNTIF($C$5:$C$25,"<"&I8) -> 0 | L8: =INDIRECT(ADDRESS(K8+4,3)) -> Marked | M8: =INDIRECT(ADDRESS(K8+5,3)) -> 0 | N8: =INDIRECT(ADDRESS(K8+4,5)) -> indicated | O8: =INDIRECT(ADDRESS(K8+5,5)) -> 0 | R8: 1.5 | S8: 1.50013 | T8: =-'OC3000 Values'!F9 -> -8.4e-05 | U8: =S8+T8 -> 1.500046 | V8: =R8-U8 -> -4.6e-05
C9: =D9/$C$2 -> 0.08 | D9: 0.8 | F9: =E9-D9 -> -0.8 | G9: =J22 -> 1.6e-05 | H9: =-(F9+G9) -> 0.799984 | I9: =Worksheet!F37 -> 0 | J9: =(I9-L9)/(M9-L9)*(O9-N9)+N9 -> #VALUE! | K9: =COUNTIF($C$5:$C$25,"<"&I9) -> 0 | L9: =INDIRECT(ADDRESS(K9+4,3)) -> Marked | M9: =INDIRECT(ADDRESS(K9+5,3)) -> 0 | N9: =INDIRECT(ADDRESS(K9+4,5)) -> indicated | O9: =INDIRECT(ADDRESS(K9+5,5)) -> 0 | R9: 2 | S9: 2.00009 | T9: =-'OC3000 Values'!F10 -> -7.2e-05 | U9: =S9+T9 -> 2.000018 | V9: =R9-U9 -> -1.8e-05
C10: =D10/$C$2 -> 0.1 | D10: 1 | E10: 0.99989 | F10: =E10-D10 -> -0.00011 | G10: =J23 -> 4.4e-05 | H10: =-(F10+G10) -> 6.6e-05 | I10: =Worksheet!F38 -> 0 | J10: =(I10-L10)/(M10-L10)*(O10-N10)+N10 -> #VALUE! | K10: =COUNTIF($C$5:$C$25,"<"&I10) -> 0 | L10: =INDIRECT(ADDRESS(K10+4,3)) -> Marked | M10: =INDIRECT(ADDRESS(K10+5,3)) -> 0 | N10: =INDIRECT(ADDRESS(K10+4,5)) -> indicated | O10: =INDIRECT(ADDRESS(K10+5,5)) -> 0 | R10: 2.5 | S10: 2.50017 | T10: =-'OC3000 Values'!F11 -> -0.000116 | U10: =S10+T10 -> 2.500054 | V10: =R10-U10 -> -5.4e-05
C11: =D11/$C$2 -> 0.12 | D11: 1.2 | F11: =E11-D11 -> -1.2 | G11: =J24 -> 8e-06 | H11: =-(F11+G11) -> 1.199992 | I11: =Worksheet!F39 -> 0 | J11: =(I11-L11)/(M11-L11)*(O11-N11)+N11 -> #VALUE! | K11: =COUNTIF($C$5:$C$25,"<"&I11) -> 0 | L11: =INDIRECT(ADDRESS(K11+4,3)) -> Marked | M11: =INDIRECT(ADDRESS(K11+5,3)) -> 0 | N11: =INDIRECT(ADDRESS(K11+4,5)) -> indicated | O11: =INDIRECT(ADDRESS(K11+5,5)) -> 0 | R11: 3 | S11: 3.00025 | T11: =-'OC3000 Values'!F12 -> -0.000158 | U11: =S11+T11 -> 3.000092 | V11: =R11-U11 -> -9.2e-05
C12: =D12/$C$2 -> 0.14 | D12: 1.4 | F12: =E12-D12 -> -1.4 | G12: =J25 -> -2.8e-05 | H12: =-(F12+G12) -> 1.400028 | I12: =Worksheet!F40 -> 0 | J12: =(I12-L12)/(M12-L12)*(O12-N12)+N12 -> #VALUE! | K12: =COUNTIF($C$5:$C$25,"<"&I12) -> 0 | L12: =INDIRECT(ADDRESS(K12+4,3)) -> Marked | M12: =INDIRECT(ADDRESS(K12+5,3)) -> 0 | N12: =INDIRECT(ADDRESS(K12+4,5)) -> indicated | O12: =INDIRECT(ADDRESS(K12+5,5)) -> 0 | R12: 3.5 | S12: 3.5003 | T12: =-'OC3000 Values'!F13 -> -0.000156 | U12: =S12+T12 -> 3.500144 | V12: =R12-U12 -> -0.000144
C13: =D13/$C$2 -> 0.16 | D13: 1.6 | F13: =E13-D13 -> -1.6 | G13: =J26 -> -4.04e-05 | H13: =-(F13+G13) -> 1.6000404 | I13: =Worksheet!F41 -> 0 | J13: =(I13-L13)/(M13-L13)*(O13-N13)+N13 -> #VALUE! | K13: =COUNTIF($C$5:$C$25,"<"&I13) -> 0 | L13: =INDIRECT(ADDRESS(K13+4,3)) -> Marked | M13: =INDIRECT(ADDRESS(K13+5,3)) -> 0 | N13: =INDIRECT(ADDRESS(K13+4,5)) -> indicated | O13: =INDIRECT(ADDRESS(K13+5,5)) -> 0 | R13: 4 | S13: 4.00038 | T13: =-'OC3000 Values'!F14 -> -0.000191 | U13: =S13+T13 -> 4.000189 | V13: =R13-U13 -> -0.000189
C14: =D14/$C$2 -> 0.18 | D14: 1.8 | F14: =E14-D14 -> -1.8 | G14: =J27 -> -2.92e-05 | H14: =-(F14+G14) -> 1.8000292 | I14: =Worksheet!F42 -> 0 | J14: =(I14-L14)/(M14-L14)*(O14-N14)+N14 -> #VALUE! | K14: =COUNTIF($C$5:$C$25,"<"&I14) -> 0 | L14: =INDIRECT(ADDRESS(K14+4,3)) -> Marked | M14: =INDIRECT(ADDRESS(K14+5,3)) -> 0 | N14: =INDIRECT(ADDRESS(K14+4,5)) -> indicated | O14: =INDIRECT(ADDRESS(K14+5,5)) -> 0 | R14: 4.5 | S14: 4.50038 | T14: =-'OC3000 Values'!F15 -> -0.000215 | U14: =S14+T14 -> 4.500165 | V14: =R14-U14 -> -0.000165
C15: =D15/$C$2 -> 0.2 | D15: 2 | E15: 1.99993 | F15: =E15-D15 -> -7e-05 | G15: =J28 -> -1.8e-05 | H15: =-(F15+G15) -> 8.8e-05 | I15: =Worksheet!F43 -> 0 | J15: =(I15-L15)/(M15-L15)*(O15-N15)+N15 -> #VALUE! | K15: =COUNTIF($C$5:$C$25,"<"&I15) -> 0 | L15: =INDIRECT(ADDRESS(K15+4,3)) -> Marked | M15: =INDIRECT(ADDRESS(K15+5,3)) -> 0 | N15: =INDIRECT(ADDRESS(K15+4,5)) -> indicated | O15: =INDIRECT(ADDRESS(K15+5,5)) -> 0 | R15: 5 | S15: 5.00042 | T15: =-'OC3000 Values'!F16 -> -0.000194 | U15: =S15+T15 -> 5.000226 | V15: =R15-U15 -> -0.000226
C16: =D16/$C$2 -> 0.22 | D16: 2.2 | F16: =E16-D16 -> -2.2 | G16: =J29 -> -3.24e-05 | H16: =-(F16+G16) -> 2.2000324 | R16: 5.5 | S16: 5.50046 | T16: =-'OC3000 Values'!F17 -> -0.000213 | U16: =S16+T16 -> 5.500247 | V16: =R16-U16 -> -0.000247
C17: =D17/$C$2 -> 0.24 | D17: 2.4 | F17: =E17-D17 -> -2.4 | G17: =J30 -> -4.68e-05 | H17: =-(F17+G17) -> 2.4000468 | I17: Interp. Correction factors for obtaining TRUE OC100 Error | R17: 6 | S17: 6.00047 | T17: =-'OC3000 Values'!F18 -> -0.000231 | U17: =S17+T17 -> 6.000239 | V17: =R17-U17 -> -0.000239
C18: =D18/$C$2 -> 0.26 | D18: 2.6 | F18: =E18-D18 -> -2.6 | G18: =J31 -> -6.16e-05 | H18: =-(F18+G18) -> 2.6000616 | I18: known Col. Lookup (The value from the known column for which you want a corresponding unknown-other column value) | J18: Unknown. Column. result | K18: Ct of numbers< known column lookup in the known column. | L18: known column low | M18: known column high | N18: unknown col. Low | O18: unknown column high | R18: 6.5 | S18: 6.50043 | T18: =-'OC3000 Values'!F19 -> -0.000232 | U18: =S18+T18 -> 6.500198 | V18: =R18-U18 -> -0.000198
C19: =D19/$C$2 -> 0.28 | D19: 2.8 | F19: =E19-D19 -> -2.8 | G19: =J32 -> -7.68e-05 | H19: =-(F19+G19) -> 2.8000768 | I19: =D6 -> 0.2 | J19: =(I19-L19)/(M19-L19)*(O19-N19)+N19 -> -1.04e-05 | K19: =COUNTIF($R$5:$R$65,"<"&I19) -> 1 | L19: =INDIRECT(ADDRESS(K19+4,18)) -> 0 | M19: =INDIRECT(ADDRESS(K19+5,18)) -> 0.5 | N19: =INDIRECT(ADDRESS(K19+4,22)) -> 0 | O19: =INDIRECT(ADDRESS(K19+5,22)) -> -2.6e-05 | R19: 7 | S19: 7.00055 | T19: =-'OC3000 Values'!F20 -> -0.000196 | U19: =S19+T19 -> 7.000354 | V19: =R19-U19 -> -0.000354
